Workbook

Sheet CS
A1: Lv | B1: スキル名 | C1: ルビ | D1: 系統 | E1: 行動 | F1: HP消費 | G1: AP消費 | H1: データ | I1: 効果 | J1: 効果説明 | K1: 取得条件 | L1: 出力確認 | M1: ダブり確認 | N1: アニメ | O1: 戦闘ルール | P1: 盾装備でデメリットは威力が下がる、軽減値が増える。 | Q1: モンク シーフ レンジャー スカウト ウィザード アルケミスト イリュージョニスト エレメント・マスター クレリック ビショップ プリースト パラディン ゴブリン オーガ トレント インプ エンジェル ソードマスター スピアマスター ブロウマスター シールドマスター ソードセイント スピアセイント ブロウセイント シールドセイント
B2: 1:初級 1 2:下級 23 3:中級 34 4:上級 56 5:下級神 7 6:中級神 89 7:上級神 10 | C2: 35 55 75 95 115 145 175 攻撃追加+1 攻撃回数:2 2倍加 など | D2: 条件 条件系統 | H2: 指揮 戦術 威圧 看破 索敵 隠密 生存 罠設置 農耕 伐採 採掘 錬成 統率 交渉 政治 信仰 | J2: 範囲について 単体,全体,縦,ライン 前後ろ縦を選択してダメージ,周囲(同じ列のみ) 効果に「連鎖」があると周囲に50%ダメージ | K2: 3.魔法強化 3.射程 4倍速 4.魔法極強化 4.三重 | M2: 回復:35 魔力105~210 10.5~21 | N2: 回復:115 魔力565~1130 34.5~69 | T2: 0.3
B3: 微5~10 小11~20 中21~35 大36~50 極51~ | C3: 〇〇の接続 で魔法取得 〇〇魔法強化 | I3: 攻撃手段:魔法 特殊:攻撃 | J3: 攻撃手段:魔法 特殊:攻撃 | K3: 属性: ロール: 技能: スキル:|
J4: =IFERROR(LET(_xlpm.v, VLOOKUP($I4,'用語辞書'!$A:$B,COLUMN('用語辞書'!B$1),FALSE), IF(_xlpm.v=0,"",_xlpm.v) ),"") | L4: =IF(OR(COUNTIF('クラス'!$A$1:$A$1267,$B4)>0,$B4="",$M4=""),"",True)
J5: =IFERROR(LET(_xlpm.v, VLOOKUP($I5,'用語辞書'!$A:$B,COLUMN('用語辞書'!B$1),FALSE), IF(_xlpm.v=0,"",_xlpm.v) ),"") | L5: =IF(OR(COUNTIF('クラス'!$A$1:$A$1267,$B5)>0,$B5="",$M5=""),"",True)
J6: =IFERROR(LET(_xlpm.v, VLOOKUP($I6,'用語辞書'!$A:$B,COLUMN('用語辞書'!B$1),FALSE), IF(_xlpm.v=0,"",_xlpm.v) ),"") | L6: =IF(OR(COUNTIF('クラス'!$A$1:$A$1267,$B6)>0,$B6="",$M6=""),"",True) | M6: =IF(COUNTIF($B$1:$C5, $B6), "", "存在しない") -> 存在しない
C7: ="------------基礎技 ------------" -> ------------基礎技 ------------ | J7: =IFERROR(LET(_xlpm.v, VLOOKUP($I7,'用語辞書'!$A:$B,COLUMN('用語辞書'!B$1),FALSE), IF(_xlpm.v=0,"",_xlpm.v) ),"") | L7: =IF(OR(COUNTIF('クラス'!$A$1:$A$1267,$B7)>0,$B7="",$M7=""),"",True) | M7: =IF(COUNTIF($B$1:$C6, $B7), "", "存在しない") -> 存在しない
B8: 肉体攻撃 | D8: 系統 | E8: スキルタイプ | F8: HP消費 | G8: AP消費 | H8: 効果 | J8: =IFERROR(LET(_xlpm.v, VLOOKUP($I8,'用語辞書'!$A:$B,COLUMN('用語辞書'!B$1),FALSE), IF(_xlpm.v=0,"",_xlpm.v) ),"") | L8: =IF(OR(COUNTIF('クラス'!$A$1:$A$1267,$B8)>0,$B8="",$M8=""),"",True) -> TRUE | M8: =IF(COUNTIF($B$1:$C7, $B8), "", "存在しない") -> 存在しない
A9: 1 | B9: 角 | E9: A | G9: 60 | H9: 攻撃手段:角 物理+25 判定:攻撃 | J9: =IFERROR(LET(_xlpm.v, VLOOKUP($I9,'用語辞書'!$A:$B,COLUMN('用語辞書'!B$1),FALSE), IF(_xlpm.v=0,"",_xlpm.v) ),"") | L9: =IF(OR(COUNTIF('クラス'!$A$1:$A$1267,$B9)>0,$B9="",$M9=""),"",True) -> TRUE | M9: =IF(COUNTIF($B$1:$C8, $B9), "", "存在しない") -> 存在しない | N9: 角
A10: 2 | B10: 牙 | E10: A | G10: 30 | H10: 攻撃手段:牙 物理+20 判定:攻撃 | J10: =IFERROR(LET(_xlpm.v, VLOOKUP($I10,'用語辞書'!$A:$B,COLUMN('用語辞書'!B$1),FALSE), IF(_xlpm.v=0,"",_xlpm.v) ),"") | L10: =IF(OR(COUNTIF('クラス'!$A$1:$A$1267,$B10)>0,$B10="",$M10=""),"",True) -> TRUE | M10: =IF(COUNTIF($B$1:$C9, $B10), "", "存在しない") -> 存在しない | N10: 牙
A11: 3 | B11: 爪 | E11: A | G11: 40 | H11: 攻撃手段:爪 物理+15 攻撃回数:2 判定:攻撃 | J11: =IFERROR(LET(_xlpm.v, VLOOKUP($I11,'用語辞書'!$A:$B,COLUMN('用語辞書'!B$1),FALSE), IF(_xlpm.v=0,"",_xlpm.v) ),"") | L11: =IF(OR(COUNTIF('クラス'!$A$1:$A$1267,$B11)>0,$B11="",$M11=""),"",True) -> TRUE | M11: =IF(COUNTIF($B$1:$C10, $B11), "", "存在しない") -> 存在しない | N11: 爪
A12: 4 | B12: 尾 | E12: A | G12: 20 | H12: 攻撃手段:尾 物理+15 判定:攻撃 | J12: =IFERROR(LET(_xlpm.v, VLOOKUP($I12,'用語辞書'!$A:$B,COLUMN('用語辞書'!B$1),FALSE), IF(_xlpm.v=0,"",_xlpm.v) ),"") | L12: =IF(OR(COUNTIF('クラス'!$A$1:$A$1267,$B12)>0,$B12="",$M12=""),"",True) -> TRUE | M12: =IF(COUNTIF($B$1:$C11, $B12), "", "存在しない") -> 存在しない | N12: 尾
A13: 5 | B13: 尾針 | E13: A | G13: 20 | H13: 攻撃手段:尾 物理+25 判定:攻撃 | J13: =IFERROR(LET(_xlpm.v, VLOOKUP($I13,'用語辞書'!$A:$B,COLUMN('用語辞書'!B$1),FALSE), IF(_xlpm.v=0,"",_xlpm.v) ),"") | L13: =IF(OR(COUNTIF('クラス'!$A$1:$A$1267,$B13)>0,$B13="",$M13=""),"",True) -> TRUE | M13: =IF(COUNTIF($B$1:$C12, $B13), "", "存在しない") -> 存在しない
A14: 6 | B14: 尾の巻き付き | E14: A | G14: 70 | H14: 攻撃手段:尾 物理+10 拘束+30 判定:攻撃 | J14: =IFERROR(LET(_xlpm.v, VLOOKUP($I14,'用語辞書'!$A:$B,COLUMN('用語辞書'!B$1),FALSE), IF(_xlpm.v=0,"",_xlpm.v) ),"") | L14: =IF(OR(COUNTIF('クラス'!$A$1:$A$1267,$B14)>0,$B14="",$M14=""),"",True) -> TRUE | M14: =IF(COUNTIF($B$1:$C13, $B14), "", "存在しない") -> 存在しない
A15: 7 | B15: 翼 | E15: A | G15: 40 | H15: 攻撃手段:翼 物理+10 ガード+15 攻撃回数:2 判定:攻撃 | J15: =IFERROR(LET(_xlpm.v, VLOOKUP($I15,'用語辞書'!$A:$B,COLUMN('用語辞書'!B$1),FALSE), IF(_xlpm.v=0,"",_xlpm.v) ),"") | L15: =IF(OR(COUNTIF('クラス'!$A$1:$A$1267,$B15)>0,$B15="",$M15=""),"",True) -> TRUE | M15: =IF(COUNTIF($B$1:$C14, $B15), "", "存在しない") -> 存在しない
A16: 8 | J16: =IFERROR(LET(_xlpm.v, VLOOKUP($I16,'用語辞書'!$A:$B,COLUMN('用語辞書'!B$1),FALSE), IF(_xlpm.v=0,"",_xlpm.v) ),"") | L16: =IF(OR(COUNTIF('クラス'!$A$1:$A$1267,$B16)>0,$B16="",$M16=""),"",True) | M16: =IF(COUNTIF($B$1:$C15, $B16), "", "存在しない") -> 存在しない
A17: 9 | B17: 突撃 | J17: =IFERROR(LET(_xlpm.v, VLOOKUP($I17,'用語辞書'!$A:$B,COLUMN('用語辞書'!B$1),FALSE), IF(_xlpm.v=0,"",_xlpm.v) ),"") | L17: =IF(OR(COUNTIF('クラス'!$A$1:$A$1267,$B17)>0,$B17="",$M17=""),"",True) -> TRUE | M17: =IF(COUNTIF($B$1:$C16, $B17), "", "存在しない") -> 存在しない | N17: #VALUE!
A18: 10 | J18: =IFERROR(LET(_xlpm.v, VLOOKUP($I18,'用語辞書'!$A:$B,COLUMN('用語辞書'!B$1),FALSE), IF(_xlpm.v=0,"",_xlpm.v) ),"") | L18: =IF(OR(COUNTIF('クラス'!$A$1:$A$1267,$B18)>0,$B18="",$M18=""),"",True) | M18: =IF(COUNTIF($B$1:$C17, $B18), "", "存在しない") -> 存在しない
J19: =IFERROR(LET(_xlpm.v, VLOOKUP($I19,'用語辞書'!$A:$B,COLUMN('用語辞書'!B$1),FALSE), IF(_xlpm.v=0,"",_xlpm.v) ),"") | L19: =IF(OR(COUNTIF('クラス'!$A$1:$A$1267,$B19)>0,$B19="",$M19=""),"",True) | M19: =IF(COUNTIF($B$1:$C18, $B19), "", "存在しない") -> 存在しない
J20: =IFERROR(LET(_xlpm.v, VLOOKUP($I20,'用語辞書'!$A:$B,COLUMN('用語辞書'!B$1),FALSE), IF(_xlpm.v=0,"",_xlpm.v) ),"") | L20: =IF(OR(COUNTIF('クラス'!$A$1:$A$1267,$B20)>0,$B20="",$M20=""),"",True) | M20: =IF(COUNTIF($B$1:$C19, $B20), "", "存在しない") -> 存在しない
C21: ="------------ 薬 ------------" -> ------------ 薬 ------------ | J21: =IFERROR(LET(_xlpm.v, VLOOKUP($I21,'用語辞書'!$A:$B,COLUMN('用語辞書'!B$1),FALSE), IF(_xlpm.v=0,"",_xlpm.v) ),"") | L21: =IF(OR(COUNTIF('クラス'!$A$1:$A$1267,$B21)>0,$B21="",$M21=""),"",True) | M21: =IF(COUNTIF($B$1:$C19, $B21), "", "存在しない") -> 存在しない
A22: 1 | B22: 薬草 | H22: 再生+5 効果時間6t | J22: =IFERROR(LET(_xlpm.v, VLOOKUP($I22,'用語辞書'!$A:$B,COLUMN('用語辞書'!B$1),FALSE), IF(_xlpm.v=0,"",_xlpm.v) ),"") | L22: =IF(OR(COUNTIF('クラス'!$A$1:$A$1267,$B22)>0,$B22="",$M22=""),"",True) -> TRUE | M22: =IF(COUNTIF($B$1:$C20, $B22), "", "存在しない") -> 存在しない
A23: 2 | B23: 水薬 | H23: 回復+20 再生+5 効果時間6t | J23: =IFERROR(LET(_xlpm.v, VLOOKUP($I23,'用語辞書'!$A:$B,COLUMN('用語辞書'!B$1),FALSE), IF(_xlpm.v=0,"",_xlpm.v) ),"") | L23: =IF(OR(COUNTIF('クラス'!$A$1:$A$1267,$B23)>0,$B23="",$M23=""),"",True) -> TRUE | M23: =IF(COUNTIF($B$1:$C21, $B23), "", "存在しない") -> 存在しない
A24: 3 | J24: =IFERROR(LET(_xlpm.v, VLOOKUP($I24,'用語辞書'!$A:$B,COLUMN('用語辞書'!B$1),FALSE), IF(_xlpm.v=0,"",_xlpm.v) ),"") | L24: =IF(OR(COUNTIF('クラス'!$A$1:$A$1267,$B24)>0,$B24="",$M24=""),"",True) | M24: =IF(COUNTIF($B$1:$C22, $B24), "", "存在しない") -> 存在しない
A25: 4 | J25: =IFERROR(LET(_xlpm.v, VLOOKUP($I25,'用語辞書'!$A:$B,COLUMN('用語辞書'!B$1),FALSE), IF(_xlpm.v=0,"",_xlpm.v) ),"") | L25: =IF(OR(COUNTIF('クラス'!$A$1:$A$1267,$B25)>0,$B25="",$M25=""),"",True) | M25: =IF(COUNTIF($B$1:$C23, $B25), "", "存在しない") -> 存在しない
A26: 5 | B26: 霊薬 | H26: 回復+80 | J26: =IFERROR(LET(_xlpm.v, VLOOKUP($I26,'用語辞書'!$A:$B,COLUMN('用語辞書'!B$1),FALSE), IF(_xlpm.v=0,"",_xlpm.v) ),"") | L26: =IF(OR(COUNTIF('クラス'!$A$1:$A$1267,$B26)>0,$B26="",$M26=""),"",True) -> TRUE | M26: =IF(COUNTIF($B$1:$C24, $B26), "", "存在しない") -> 存在しない
A27: 6 | J27: =IFERROR(LET(_xlpm.v, VLOOKUP($I27,'用語辞書'!$A:$B,COLUMN('用語辞書'!B$1),FALSE), IF(_xlpm.v=0,"",_xlpm.v) ),"") | L27: =IF(OR(COUNTIF('クラス'!$A$1:$A$1267,$B27)>0,$B27="",$M27=""),"",True) | M27: =IF(COUNTIF($B$1:$C25, $B27), "", "存在しない") -> 存在しない
A28: 7 | J28: =IFERROR(LET(_xlpm.v, VLOOKUP($I28,'用語辞書'!$A:$B,COLUMN('用語辞書'!B$1),FALSE), IF(_xlpm.v=0,"",_xlpm.v) ),"") | L28: =IF(OR(COUNTIF('クラス'!$A$1:$A$1267,$B28)>0,$B28="",$M28=""),"",True) | M28: =IF(COUNTIF($B$1:$C26, $B28), "", "存在しない") -> 存在しない
A29: 8 | J29: =IFERROR(LET(_xlpm.v, VLOOKUP($I29,'用語辞書'!$A:$B,COLUMN('用語辞書'!B$1),FALSE), IF(_xlpm.v=0,"",_xlpm.v) ),"") | L29: =IF(OR(COUNTIF('クラス'!$A$1:$A$1267,$B29)>0,$B29="",$M29=""),"",True) | M29: =IF(COUNTIF($B$1:$C27, $B29), "", "存在しない") -> 存在しない
J30: =IFERROR(LET(_xlpm.v, VLOOKUP($I30,'用語辞書'!$A:$B,COLUMN('用語辞書'!B$1),FALSE), IF(_xlpm.v=0,"",_xlpm.v) ),"") | L30: =IF(OR(COUNTIF('クラス'!$A$1:$A$1267,$B30)>0,$B30="",$M30=""),"",True) | M30: =IF(COUNTIF($B$1:$C28, $B30), "", "存在しない") -> 存在しない
J31: =IFERROR(LET(_xlpm.v, VLOOKUP($I31,'用語辞書'!$A:$B,COLUMN('用語辞書'!B$1),FALSE), IF(_xlpm.v=0,"",_xlpm.v) ),"") | L31: =IF(OR(COUNTIF('クラス'!$A$1:$A$1267,$B31)>0,$B31="",$M31=""),"",True) | M31: =IF(COUNTIF($B$1:$C29, $B31), "", "存在しない") -> 存在しない
J32: =IFERROR(LET(_xlpm.v, VLOOKUP($I32,'用語辞書'!$A:$B,COLUMN('用語辞書'!B$1),FALSE), IF(_xlpm.v=0,"",_xlpm.v) ),"") | L32: =IF(OR(COUNTIF('クラス'!$A$1:$A$1267,$B32)>0,$B32="",$M32=""),"",True) | M32: =IF(COUNTIF($B$1:$C30, $B32), "", "存在しない") -> 存在しない
J33: =IFERROR(LET(_xlpm.v, VLOOKUP($I33,'用語辞書'!$A:$B,COLUMN('用語辞書'!B$1),FALSE), IF(_xlpm.v=0,"",_xlpm.v) ),"") | L33: =IF(OR(COUNTIF('クラス'!$A$1:$A$1267,$B33)>0,$B33="",$M33=""),"",True) | M33: =IF(COUNTIF($B$1:$C31, $B33), "", "存在しない") -> 存在しない
L34: =IF(OR(COUNTIF('クラス'!$A$1:$A$1267,$B34)>0,$B34="",$M34=""),"",True)
C35: ="------------地形 ------------" -> ------------地形 ------------ | J35: =IFERROR(LET(_xlpm.v, VLOOKUP($I35,'用語辞書'!$A:$B,COLUMN('用語辞書'!B$1),FALSE), IF(_xlpm.v=0,"",_xlpm.v) ),"") | L35: =IF(OR(COUNTIF('クラス'!$A$1:$A$1267,$B35)>0,$B35="",$M35=""),"",True) | M35: =IF(COUNTIF($B$1:$C33, $B35), "", "存在しない") -> 存在しない
B36: 平地 | E36: P | J36: =IFERROR(LET(_xlpm.v, VLOOKUP($I36,'用語辞書'!$A:$B,COLUMN('用語辞書'!B$1),FALSE), IF(_xlpm.v=0,"",_xlpm.v) ),"") | L36: =IF(OR(COUNTIF('クラス'!$A$1:$A$1267,$B36)>0,$B36="",$M36=""),"",True) -> TRUE | M36: =IF(COUNTIF($B$1:$C34, $B36), "", "存在しない") -> 存在しない
B37: 森 | E37: P | J37: =IFERROR(LET(_xlpm.v, VLOOKUP($I37,'用語辞書'!$A:$B,COLUMN('用語辞書'!B$1),FALSE), IF(_xlpm.v=0,"",_xlpm.v) ),"") | L37: =IF(OR(COUNTIF('クラス'!$A$1:$A$1267,$B37)>0,$B37="",$M37=""),"",True) -> TRUE | M37: =IF(COUNTIF($B$1:$C35, $B37), "", "存在しない") -> 存在しない
B38: 山岳 | E38: P | J38: =IFERROR(LET(_xlpm.v, VLOOKUP($I38,'用語辞書'!$A:$B,COLUMN('用語辞書'!B$1),FALSE), IF(_xlpm.v=0,"",_xlpm.v) ),"") | L38: =IF(OR(COUNTIF('クラス'!$A$1:$A$1267,$B38)>0,$B38="",$M38=""),"",True) -> TRUE | M38: =IF(COUNTIF($B$1:$C36, $B38), "", "存在しない") -> 存在しない
B39: 丘陵 | E39: P | J39: =IFERROR(LET(_xlpm.v, VLOOKUP($I39,'用語辞書'!$A:$B,COLUMN('用語辞書'!B$1),FALSE), IF(_xlpm.v=0,"",_xlpm.v) ),"") | L39: =IF(OR(COUNTIF('クラス'!$A$1:$A$1267,$B39)>0,$B39="",$M39=""),"",True) -> TRUE | M39: =IF(COUNTIF($B$1:$C37, $B39), "", "存在しない") -> 存在しない
B40: 河川 | E40: P | J40: =IFERROR(LET(_xlpm.v, VLOOKUP($I40,'用語辞書'!$A:$B,COLUMN('用語辞書'!B$1),FALSE), IF(_xlpm.v=0,"",_xlpm.v) ),"") | L40: =IF(OR(COUNTIF('クラス'!$A$1:$A$1267,$B40)>0,$B40="",$M40=""),"",True) -> TRUE | M40: =IF(COUNTIF($B$1:$C38, $B40), "", "存在しない") -> 存在しない
...

Sheet クラス
A1: 名前 | B1: ルビ | C1: 種類 | D1: 合計 | E1: Tire | F1: HP | G1: MP | H1: ST | I1: 攻撃 | J1: 防御 | K1: 魔力 | L1: 精神 | M1: 速度 | N1: 命中 | O1: SIZ | P1: APP | Q1: 物理耐性 | R1: 魔法耐性 | S1: 射撃耐性 | T1: 切断耐性 | U1: 貫通耐性 | V1: 打撃耐性 | W1: 炎耐性 | X1: 氷耐性 | Y1: 雷耐性 | Z1: 毒耐性 | AA1: 光耐性 | AB1: 闇耐性 | AC1: 精神耐性 | AD1: 怯み耐性 | AE1: 出血耐性 | AF1: 拘束耐性 | AG1: 幻覚耐性 | AH1: Cr率耐性 | AI1: Cr威力耐性 | AJ1: 指揮 | AK1: 威圧 | AL1: 看破 | AM1: 早業 | AN1: 技術 | AO1: 変装 | AP1: 飛行 | AQ1: 隠密 | AR1: 索敵 | AS1: 農業 | AT1: 林業 | AU1: 漁業 | AV1: 工業 | AW1: 統治 | AX1: 交渉 | AY1: 魔術 | AZ1: 信仰 | BA1: 角 | BB1: 牙 | BC1: 爪 | BD1: 尾 | BE1: 翼 | BF1: 装甲 | BG1: Skill1 | BH1: Skill2 | BI1: Skill3 | BJ1: Skill4 | BK1: Skill5 | BL1: Skill6 | BM1: Skill7 | BN1: Skill8 | BO1: Skill9 | BP1: Skill10 | BQ1: 合計Lv | BR1: 条件クラス | BS1: 条件スキル | BT1: 条件施設 | BU1: 詳細 | BV1: 増加条件 | BW1: コスト | BX1: 穀物 | BY1: 野菜 | BZ1: 肉 | CA1: 魚 | CB1: 魂 | CC1: 死体 | CD1: 脚数 | CE1: 環境 | CF1: 装備枠 | CG1: 武器1 | CH1: 武器2 | CI1: 頭 | CJ1: 体 | CK1: 足 | CL1: 装飾1 | CM1: 装飾2 | CN1: 画像ID | CO1: 適正土地 | CP1: 苦手土地 | CQ1: 必要正魂APP | CR1: 必要負魂APP
Q2: 50 | R2: 51 | T2: 52 | U2: 53 | V2: 54 | W2: 52 | X2: 53 | Y2: 54 | Z2: 55 | AA2: 56 | AB2: 57 | AC2: 58 | AD2: 59 | AE2: 60 | AF2: 61 | AG2: 62 | AH2: 63 | AI2: 64 | AJ2: 指揮 | AK2: 部隊への命令効率を高める。士気上昇量やバフ効果量が増加し、部隊スキルの性能が向上する。
AJ3: 威圧 | AK3: 騙すを併合。敵やNPCに心理的圧力を与える。敵士気低下や怯え付与、会話時の威圧成功率が上昇する。
AJ4: 看破 | AK4: 知識を含む。敵能力・弱点・嘘・罠・アイテムの性質を見破る。不意打ち耐性や情報取得能力が向上する。
AJ5: 早業 | AK5: 軽業を併合。攻撃速度や回避率が上昇し、移動系スキルの消費が軽減される。連撃性能が向上する。
AJ6: 技術 | AK6: 装置操作・罠設置・修理・制作補助能力。戦闘中のトラップ性能や道具効果が向上する。
AJ7: 隠密 | AK7: 発見されにくくなる。奇襲成功率や離脱成功率が上昇し、不意打ち時の威力が増加する。
AJ8: 索敵 | AK8: 敵や資源を発見しやすくなる。遭遇率制御、罠発見、危険察知能力が向上する。
AJ9: 農業 | AK9: 穀物・家畜など農業生産効率を上昇させる。災害による収穫減少を軽減する。
AJ10: 林業 | AK10: 木材資源の取得量と森林管理効率を上昇させる。森林枯渇速度を軽減する。
AJ11: 漁業 | AK11: 水域資源の取得量を上昇させる。食料安定度に補正を与える。
AJ12: 工業 | AK12: 加工・生産効率を上昇させる。装備や施設の生産速度が向上する。
AJ13: 統治 | AK13: 都市安定度や治安を向上させる。反乱発生率を低下させ、維持費効率を改善する。
AJ14: 交渉 | AK14: 交易価格や外交成功率を上昇させる。条約締結や取引条件が有利になる。
... AJ16: 信仰 | AK16: 宗教効果や祝福系能力を強化する。士気回復や精神耐性補正が向上する。
BW17: 種族 | BX17: 穀物 | BY17: 野菜 | BZ17: 肉 | CA17: 魚
A18: ヒューマン | C18: 人族 | D18: =SUM(AJ18:AZ18,F18:N18)&"/"&SUM(F18:N18)&"/"&SUM(AJ18:AZ18) -> 775/460/315 | E18: 1 | F18: 75 | I18: 70 | J18: 70 | K18: 25 | L18: 70 | M18: 70 | N18: 80 | O18: 170 | P18: 0 | AJ18: 35 | AK18: 35 | AL18: 35 | AM18: 35 | AN18: 35 | AO18: 0 | AP18: 0 | AQ18: 35 | AR18: 35 | AS18: 0 | AT18: 0 | AU18: 0 | AV18: 0 | AW18: 35 | AX18: 35 | AY18: 0 | AZ18: 0 | BA18: 0 | BB18: 0 | BC18: 0 | BD18: 0 | BE18: 0 | BF18: 0 | BG18: {=IF($A18="","", INDEX(CS!$B$1:$B$15026,MATCH($A18,CS!$B:$B,0)+COLUMN(A$1),1))} | BH18: {=IF($A18="","", INDEX(CS!$B$1:$B$15026,MATCH($A18,CS!$B:$B,0)+COLUMN(B$1),1))} | BI18: {=IF($A18="","", INDEX(CS!$B$1:$B$15026,MATCH($A18,CS!$B:$B,0)+COLUMN(C$1),1))} | BJ18: {=IF($A18="","", INDEX(CS!$B$1:$B$15026,MATCH($A18,CS!$B:$B,0)+COLUMN(D$1),1))} | BK18: {=IF($A18="","", INDEX(CS!$B$1:$B$15026,MATCH($A18,CS!$B:$B,0)+COLUMN(E$1),1))} | BL18: {=IF($A18="","", INDEX(CS!$B$1:$B$15026,MATCH($A18,CS!$B:$B,0)+COLUMN(F$1),1))} | BM18: {=IF($A18="","", INDEX(CS!$B$1:$B$15026,MATCH($A18,CS!$B:$B,0)+COLUMN(G$1),1))} | BN18: {=IF($A18="","", INDEX(CS!$B$1:$B$15026,MATCH($A18,CS!$B:$B,0)+COLUMN(H$1),1))} | ... BP18: {=IF($A18="","", INDEX(CS!$B$1:$B$15026,MATCH($A18,CS!$B:$B,0)+COLUMN(J$1),1))} | BV18: 食事 | BW18: 100 | BX18: 40 | BY18: 30 | BZ18: 20 | CA18: 10 | CD18: 2 | CN18: 只人 | CO18: ["平地","河川"]
A19: エルフ | C19: 人族 | D19: =SUM(AJ19:AZ19,F19:N19)&"/"&SUM(F19:N19)&"/"&SUM(AJ19:AZ19) -> 775/460/315 | E19: 1 | F19: 65 | I19: 65 | J19: 70 | K19: 25 | L19: 70 | M19: 85 | N19: 80 | O19: 170 | P19: 0 | AJ19: 35 | AK19: 0 | AL19: 35 | AM19: 35 | AN19: 0 | AO19: 0 | AP19: 0 | AQ19: 35 | AR19: 35 | AS19: 35 | AT19: 35 | AU19: 0 | AV19: 0 | AW19: 0 | AX19: 0 | AY19: 35 | AZ19: 35 | BA19: 0 | BB19: 0 | BC19: 0 | BD19: 0 | BE19: 0 | BF19: 0 | BG19: {=IF($A19="","", INDEX(CS!$B$1:$B$15026,MATCH($A19,CS!$B:$B,0)+COLUMN(A$1),1))} | BH19: {=IF($A19="","", INDEX(CS!$B$1:$B$15026,MATCH($A19,CS!$B:$B,0)+COLUMN(B$1),1))} | BI19: {=IF($A19="","", INDEX(CS!$B$1:$B$15026,MATCH($A19,CS!$B:$B,0)+COLUMN(C$1),1))} | BJ19: {=IF($A19="","", INDEX(CS!$B$1:$B$15026,MATCH($A19,CS!$B:$B,0)+COLUMN(D$1),1))} | BK19: {=IF($A19="","", INDEX(CS!$B$1:$B$15026,MATCH($A19,CS!$B:$B,0)+COLUMN(E$1),1))} | BL19: {=IF($A19="","", INDEX(CS!$B$1:$B$15026,MATCH($A19,CS!$B:$B,0)+COLUMN(F$1),1))} | BM19: {=IF($A19="","", INDEX(CS!$B$1:$B$15026,MATCH($A19,CS!$B:$B,0)+COLUMN(G$1),1))} | BN19: {=IF($A19="","", INDEX(CS!$B$1:$B$15026,MATCH($A19,CS!$B:$B,0)+COLUMN(H$1),1))} | ... BP19: {=IF($A19="","", INDEX(CS!$B$1:$B$15026,MATCH($A19,CS!$B:$B,0)+COLUMN(J$1),1))} | BV19: 食事 | BW19: 100 | BX19: 20 | BY19: 50 | BZ19: 10 | CA19: 20 | CD19: 2 | CN19: 森人 | CO19: ["森"] | CP19: ["荒野","砂漠","火山"]
A20: ドワーフ | C20: 人族 | D20: =SUM(AJ20:AZ20,F20:N20)&"/"&SUM(F20:N20)&"/"&SUM(AJ20:AZ20) -> 775/460/315 | E20: 1 | F20: 85 | I20: 80 | J20: 80 | K20: 25 | L20: 60 | M20: 50 | N20: 80 | O20: 140 | P20: 0 | AJ20: 35 | AK20: 35 | AL20: 35 | AM20: 0 | AN20: 70 | AO20: 0 | AP20: 0 | AQ20: 0 | AR20: 35 | AS20: 0 | AT20: 0 | AU20: 0 | AV20: 70 | AW20: 35 | AX20: 0 | AY20: 0 | AZ20: 0 | BA20: 0 | BB20: 0 | BC20: 0 | BD20: 0 | BE20: 0 | BF20: 0 | BG20: {=IF($A20="","", INDEX(CS!$B$1:$B$15026,MATCH($A20,CS!$B:$B,0)+COLUMN(A$1),1))} | BH20: {=IF($A20="","", INDEX(CS!$B$1:$B$15026,MATCH($A20,CS!$B:$B,0)+COLUMN(B$1),1))} | BI20: {=IF($A20="","", INDEX(CS!$B$1:$B$15026,MATCH($A20,CS!$B:$B,0)+COLUMN(C$1),1))} | BJ20: {=IF($A20="","", INDEX(CS!$B$1:$B$15026,MATCH($A20,CS!$B:$B,0)+COLUMN(D$1),1))} | BK20: {=IF($A20="","", INDEX(CS!$B$1:$B$15026,MATCH($A20,CS!$B:$B,0)+COLUMN(E$1),1))} | BL20: {=IF($A20="","", INDEX(CS!$B$1:$B$15026,MATCH($A20,CS!$B:$B,0)+COLUMN(F$1),1))} | BM20: {=IF($A20="","", INDEX(CS!$B$1:$B$15026,MATCH($A20,CS!$B:$B,0)+COLUMN(G$1),1))} | BN20: {=IF($A20="","", INDEX(CS!$B$1:$B$15026,MATCH($A20,CS!$B:$B,0)+COLUMN(H$1),1))} | ... BP20: {=IF($A20="","", INDEX(CS!$B$1:$B$15026,MATCH($A20,CS!$B:$B,0)+COLUMN(J$1),1))} | BV20: 食事 | BW20: 100 | BX20: 30 | BY20: 20 | BZ20: 40 | CA20: 10 | CD20: 2 | CN20: 土人 | CO20: ["丘陵","山岳","洞窟"] | CP20: ["沼地","湿地"]
D21: =SUM(AJ21:AZ21,F21:N21)&"/"&SUM(F21:N21)&"/"&SUM(AJ21:AZ21) -> 0/0/0 | BG21: {=IF($A21="","", INDEX(CS!$B$1:$B$15026,MATCH($A21,CS!$B:$B,0)+COLUMN(A$1),1))} | BH21: {=IF($A21="","", INDEX(CS!$B$1:$B$15026,MATCH($A21,CS!$B:$B,0)+COLUMN(B$1),1))} | BI21: {=IF($A21="","", INDEX(CS!$B$1:$B$15026,MATCH($A21,CS!$B:$B,0)+COLUMN(C$1),1))} | BJ21: {=IF($A21="","", INDEX(CS!$B$1:$B$15026,MATCH($A21,CS!$B:$B,0)+COLUMN(D$1),1))} | BK21: {=IF($A21="","", INDEX(CS!$B$1:$B$15026,MATCH($A21,CS!$B:$B,0)+COLUMN(E$1),1))} | BL21: {=IF($A21="","", INDEX(CS!$B$1:$B$15026,MATCH($A21,CS!$B:$B,0)+COLUMN(F$1),1))} | BM21: {=IF($A21="","", INDEX(CS!$B$1:$B$15026,MATCH($A21,CS!$B:$B,0)+COLUMN(G$1),1))} | BN21: {=IF($A21="","", INDEX(CS!$B$1:$B$15026,MATCH($A21,CS!$B:$B,0)+COLUMN(H$1),1))} | ... BP21: {=IF($A21="","", INDEX(CS!$B$1:$B$15026,MATCH($A21,CS!$B:$B,0)+COLUMN(J$1),1))}
A22: ビーストマン | C22: 亜人 | D22: =SUM(AJ22:AZ22,F22:N22)&"/"&SUM(F22:N22)&"/"&SUM(AJ22:AZ22) -> 710/490/220 | E22: 1 | F22: 85 | I22: 85 | J22: 65 | K22: 35 | L22: 50 | M22: 100 | N22: 70 | P22: 0 | AC22: -20 | AD22: 10 | AF22: 10 | AJ22: 0 | AK22: 50 | AL22: 0 | AM22: 50 | AN22: 0 | AO22: 0 | AP22: 0 | AQ22: 70 | AR22: 50 | AS22: 0 | AT22: 0 | AU22: 0 | AV22: 0 | AW22: 0 | AX22: 0 | AY22: 0 | AZ22: 0 | BA22: 0 | BB22: 60 | BC22: 70 | BD22: 0 | BE22: 0 | BF22: 20 | BG22: {=IF($A22="","", INDEX(CS!$B$1:$B$15026,MATCH($A22,CS!$B:$B,0)+COLUMN(A$1),1))} -> 爪 | BH22: {=IF($A22="","", INDEX(CS!$B$1:$B$15026,MATCH($A22,CS!$B:$B,0)+COLUMN(B$1),1))} -> 牙 | BI22: {=IF($A22="","", INDEX(CS!$B$1:$B$15026,MATCH($A22,CS!$B:$B,0)+COLUMN(C$1),1))} -> 野生感覚 | BJ22: {=IF($A22="","", INDEX(CS!$B$1:$B$15026,MATCH($A22,CS!$B:$B,0)+COLUMN(D$1),1))} | BK22: {=IF($A22="","", INDEX(CS!$B$1:$B$15026,MATCH($A22,CS!$B:$B,0)+COLUMN(E$1),1))} -> 獣の身軽さ | BL22: {=IF($A22="","", INDEX(CS!$B$1:$B$15026,MATCH($A22,CS!$B:$B,0)+COLUMN(F$1),1))} | BM22: {=IF($A22="","", INDEX(CS!$B$1:$B$15026,MATCH($A22,CS!$B:$B,0)+COLUMN(G$1),1))} -> 獣性 | BN22: {=IF($A22="","", INDEX(CS!$B$1:$B$15026,MATCH($A22,CS!$B:$B,0)+COLUMN(H$1),1))} | ... BP22: {=IF($A22="","", INDEX(CS!$B$1:$B$15026,MATCH($A22,CS!$B:$B,0)+COLUMN(J$1),1))} -> 獣の本能 | BV22: 食事 | BW22: 110 | BX22: 20 | BY22: 20 | BZ22: 50 | CA22: 20 | CD22: 2 | CN22: 獣人 | CO22: ["森","荒野"]
A23: ドラゴニュート | C23: 亜人 | D23: =SUM(AJ23:AZ23,F23:N23)&"/"&SUM(F23:N23)&"/"&SUM(AJ23:AZ23) -> 710/490/220 | E23: 1 | F23: 90 | I23: 90 | J23: 75 | K23: 35 | L23: 70 | M23: 55 | N23: 75 | O23: 170 | P23: 0 | Q23: 5 | R23: 5 | AD23: 15 | AG23: -15 | AJ23: 0 | AK23: 75 | AL23: 45 | AM23: 25 | AN23: 0 | AO23: 0 | AP23: 0 | AQ23: 0 | AR23: 50 | AS23: 0 | AT23: 0 | AU23: 0 | AV23: 0 | AW23: 0 | AX23: 0 | AY23: 25 | AZ23: 0 | BA23: 0 | BB23: 100 | BC23: 90 | BD23: 80 | BE23: 0 | BF23: 100 | BG23: {=IF($A23="","", INDEX(CS!$B$1:$B$15026,MATCH($A23,CS!$B:$B,0)+COLUMN(A$1),1))} -> 牙 | BH23: {=IF($A23="","", INDEX(CS!$B$1:$B$15026,MATCH($A23,CS!$B:$B,0)+COLUMN(B$1),1))} -> 爪 | BI23: {=IF($A23="","", INDEX(CS!$B$1:$B$15026,MATCH($A23,CS!$B:$B,0)+COLUMN(C$1),1))} -> 尾 | BJ23: {=IF($A23="","", INDEX(CS!$B$1:$B$15026,MATCH($A23,CS!$B:$B,0)+COLUMN(D$1),1))} | BK23: {=IF($A23="","", INDEX(CS!$B$1:$B$15026,MATCH($A23,CS!$B:$B,0)+COLUMN(E$1),1))} -> 竜鱗 | BL23: {=IF($A23="","", INDEX(CS!$B$1:$B$15026,MATCH($A23,CS!$B:$B,0)+COLUMN(F$1),1))} | BM23: {=IF($A23="","", INDEX(CS!$B$1:$B$15026,MATCH($A23,CS!$B:$B,0)+COLUMN(G$1),1))} -> 竜人の咆哮 | BN23: {=IF($A23="","", INDEX(CS!$B$1:$B$15026,MATCH($A23,CS!$B:$B,0)+COLUMN(H$1),1))} | ... BP23: {=IF($A23="","", INDEX(CS!$B$1:$B$15026,MATCH($A23,CS!$B:$B,0)+COLUMN(J$1),1))} -> 竜の肉体 | BV23: 食事 | BW23: 110 | BX23: 15 | BY23: 10 | BZ23: 70 | CA23: 15 | CD23: 2 | CN23: 竜人 | CO23: ["山岳","火山"] | CP23: ["雪原"]
A24: オーガ | C24: 亜人 | D24: =SUM(AJ24:AZ24,F24:N24)&"/"&SUM(F24:N24)&"/"&SUM(AJ24:AZ24) -> 710/490/220 | E24: 1 | F24: 110 | I24: 105 | J24: 65 | K24: 50 | L24: 45 | M24: 55 | N24: 60 | O24: 300 | P24: -25 | W24: 10 | AC24: -15 | AD24: 15 | AG24: -15 | AJ24: 20 | AK24: 100 | AL24: 25 | AM24: -30 | AN24: -25 | AO24: 0 | AP24: 0 | AQ24: 25 | AR24: 25 | AS24: 0 | AT24: 0 | AU24: 0 | AV24: 0 | AW24: 25 | AX24: 15 | AY24: 40 | AZ24: 0 | BA24: 0 | BB24: 0 | BC24: 0 | BD24: 0 | BE24: 0 | BF24: 20 | BG24: {=IF($A24="","", INDEX(CS!$B$1:$B$15026,MATCH($A24,CS!$B:$B,0)+COLUMN(A$1),1))} -> 豪腕 | BH24: {=IF($A24="","", INDEX(CS!$B$1:$B$15026,MATCH($A24,CS!$B:$B,0)+COLUMN(B$1),1))} | BI24: {=IF($A24="","", INDEX(CS!$B$1:$B$15026,MATCH($A24,CS!$B:$B,0)+COLUMN(C$1),1))} -> 強靭な肉体 | BJ24: {=IF($A24="","", INDEX(CS!$B$1:$B$15026,MATCH($A24,CS!$B:$B,0)+COLUMN(D$1),1))} | BK24: {=IF($A24="","", INDEX(CS!$B$1:$B$15026,MATCH($A24,CS!$B:$B,0)+COLUMN(E$1),1))} -> 叩き潰し | BL24: {=IF($A24="","", INDEX(CS!$B$1:$B$15026,MATCH($A24,CS!$B:$B,0)+COLUMN(F$1),1))} | BM24: {=IF($A24="","", INDEX(CS!$B$1:$B$15026,MATCH($A24,CS!$B:$B,0)+COLUMN(G$1),1))} -> 大鬼の咆哮 | BN24: {=IF($A24="","", INDEX(CS!$B$1:$B$15026,MATCH($A24,CS!$B:$B,0)+COLUMN(H$1),1))} | ... BP24: {=IF($A24="","", INDEX(CS!$B$1:$B$15026,MATCH($A24,CS!$B:$B,0)+COLUMN(J$1),1))} -> 鬼の怪力 | BV24: 食事 | BW24: 200 | BX24: 40 | BY24: 10 | BZ24: 100 | CA24: 10 | CD24: 2 | CN24: 大鬼 | CO24: ["荒野","丘陵"] | CP24: ["沼地","湿地"]
A25: ジャイアント | C25: 亜人 | D25: =SUM(AJ25:AZ25,F25:N25)&"/"&SUM(F25:N25)&"/"&SUM(AJ25:AZ25) -> 710/490/220 | E25: 1 | F25: 90 | I25: 90 | J25: 70 | K25: 25 | L25: 70 | M25: 70 | N25: 75 | O25: 550 | P25: 0 | AJ25: 35 | AK25: 35 | AL25: 35 | AM25: -15 | AN25: 35 | AO25: 0 | AP25: 0 | AQ25: 0 | AR25: 35 | AS25: 0 | AT25: 0 | AU25: 0 | AV25: 0 | AW25: 35 | AX25: 0 | AY25: 25 | AZ25: 0 | BA25: 0 | BB25: 0 | BC25: 0 | BD25: 0 | BE25: 0 | BF25: 20 | BG25: {=IF($A25="","", INDEX(CS!$B$1:$B$15026,MATCH($A25,CS!$B:$B,0)+COLUMN(A$1),1))} -> 巨人の膂力 | BH25: {=IF($A25="","", INDEX(CS!$B$1:$B$15026,MATCH($A25,CS!$B:$B,0)+COLUMN(B$1),1))} | BI25: {=IF($A25="","", INDEX(CS!$B$1:$B$15026,MATCH($A25,CS!$B:$B,0)+COLUMN(C$1),1))} -> 巨大な体躯 | BJ25: {=IF($A25="","", INDEX(CS!$B$1:$B$15026,MATCH($A25,CS!$B:$B,0)+COLUMN(D$1),1))} | BK25: {=IF($A25="","", INDEX(CS!$B$1:$B$15026,MATCH($A25,CS!$B:$B,0)+COLUMN(E$1),1))} -> 踏みつけ | BL25: {=IF($A25="","", INDEX(CS!$B$1:$B$15026,MATCH($A25,CS!$B:$B,0)+COLUMN(F$1),1))} | BM25: {=IF($A25="","", INDEX(CS!$B$1:$B$15026,MATCH($A25,CS!$B:$B,0)+COLUMN(G$1),1))} -> 巨腕薙ぎ | BN25: {=IF($A25="","", INDEX(CS!$B$1:$B$15026,MATCH($A25,CS!$B:$B,0)+COLUMN(H$1),1))} | ... BP25: {=IF($A25="","", INDEX(CS!$B$1:$B$15026,MATCH($A25,CS!$B:$B,0)+COLUMN(J$1),1))} -> 巨躯 | BV25: 食事 | BW25: 250 | BX25: 60 | BY25: 30 | BZ25: 200 | CA25: 30 | CD25: 2 | CN25: 巨人 | CO25: ["山岳","雪原"] | CP25: ["洞窟","沼地"]
A26: ゴブリン | C26: 亜人 | D26: =SUM(AJ26:AZ26,F26:N26)&"/"&SUM(F26:N26)&"/"&SUM(AJ26:AZ26) -> 710/490/220 | E26: 1 | F26: 90 | I26: 90 | J26: 65 | K26: 30 | L26: 55 | M26: 85 | N26: 75 | O26: 100 | P26: -25 | Z26: 15 | AC26: -15 | AJ26: 25 | AK26: 0 | AL26: 25 | AM26: 35 | AN26: 35 | AO26: 0 | AP26: 0 | AQ26: 75 | AR26: 75 | AS26: 0 | AT26: 0 | AU26: 0 | AV26: 0 | AW26: -25 | AX26: -25 | AY26: 0 | AZ26: 0 | BA26: 0 | BB26: 0 | BC26: 0 | BD26: 0 | BE26: 0 | BF26: 0 | BG26: {=IF($A26="","", INDEX(CS!$B$1:$B$15026,MATCH($A26,CS!$B:$B,0)+COLUMN(A$1),1))} -> 小柄 | BH26: {=IF($A26="","", INDEX(CS!$B$1:$B$15026,MATCH($A26,CS!$B:$B,0)+COLUMN(B$1),1))} | BI26: {=IF($A26="","", INDEX(CS!$B$1:$B$15026,MATCH($A26,CS!$B:$B,0)+COLUMN(C$1),1))} -> 悪知恵 | BJ26: {=IF($A26="","", INDEX(CS!$B$1:$B$15026,MATCH($A26,CS!$B:$B,0)+COLUMN(D$1),1))} | BK26: {=IF($A26="","", INDEX(CS!$B$1:$B$15026,MATCH($A26,CS!$B:$B,0)+COLUMN(E$1),1))} -> 逃げ足 | BL26: {=IF($A26="","", INDEX(CS!$B$1:$B$15026,MATCH($A26,CS!$B:$B,0)+COLUMN(F$1),1))} | BM26: {=IF($A26="","", INDEX(CS!$B$1:$B$15026,MATCH($A26,CS!$B:$B,0)+COLUMN(G$1),1))} -> 奇襲 | BN26: {=IF($A26="","", INDEX(CS!$B$1:$B$15026,MATCH($A26,CS!$B:$B,0)+COLUMN(H$1),1))} | ... BP26: {=IF($A26="","", INDEX(CS!$B$1:$B$15026,MATCH($A26,CS!$B:$B,0)+COLUMN(J$1),1))} -> 狡猾 | BV26: 食事 | BW26: 70 | BX26: 30 | BY26: 20 | BZ26: 10 | CA26: 10 | CD26: 2 | CN26: 鬼妖 | CO26: ["洞窟","荒野"] | CP26: ["雪原"]
A27: トレント | C27: 亜人 | D27: =SUM(AJ27:AZ27,F27:N27)&"/"&SUM(F27:N27)&"/"&SUM(AJ27:AZ27) -> 710/490/220 | E27: 1 | F27: 90 | I27: 90 | J27: 70 | K27: 25 | L27: 55 | M27: 85 | N27: 75 | O27: 100 | P27: 25 | Z27: 15 | AC27: -15 | AJ27: 0 | AK27: -25 | AL27: 35 | AM27: 0 | AN27: 50 | AO27: 0 | AP27: 0 | AQ27: 75 | AR27: 25 | AS27: 75 | AT27: 0 | AU27: 0 | AV27: 0 | AW27: -25 | AX27: -25 | AY27: 0 | AZ27: 35 | BA27: 0 | BB27: 0 | BC27: 0 | BD27: 0 | BE27: 0 | BF27: 120 | BG27: {=IF($A27="","", INDEX(CS!$B$1:$B$15026,MATCH($A27,CS!$B:$B,0)+COLUMN(A$1),1))} -> 樹皮 | BH27: {=IF($A27="","", INDEX(CS!$B$1:$B$15026,MATCH($A27,CS!$B:$B,0)+COLUMN(B$1),1))} | BI27: {=IF($A27="","", INDEX(CS!$B$1:$B$15026,MATCH($A27,CS!$B:$B,0)+COLUMN(C$1),1))} -> 根張り | BJ27: {=IF($A27="","", INDEX(CS!$B$1:$B$15026,MATCH($A27,CS!$B:$B,0)+COLUMN(D$1),1))} | BK27: {=IF($A27="","", INDEX(CS!$B$1:$B$15026,MATCH($A27,CS!$B:$B,0)+COLUMN(E$1),1))} -> 枝打ち | BL27: {=IF($A27="","", INDEX(CS!$B$1:$B$15026,MATCH($A27,CS!$B:$B,0)+COLUMN(F$1),1))} | BM27: {=IF($A27="","", INDEX(CS!$B$1:$B$15026,MATCH($A27,CS!$B:$B,0)+COLUMN(G$1),1))} -> 森との同化 | BN27: {=IF($A27="","", INDEX(CS!$B$1:$B$15026,MATCH($A27,CS!$B:$B,0)+COLUMN(H$1),1))} | ... BP27: {=IF($A27="","", INDEX(CS!$B$1:$B$15026,MATCH($A27,CS!$B:$B,0)+COLUMN(J$1),1))} -> 古木の生命力 | BV27: 食事 | BW27: 70 | BX27: 30 | BY27: 20 | BZ27: 10 | CA27: 10 | CD27: 2 | CN27: 鬼妖 | CO27: ["森","湿地"] | CP27: ["砂漠","火山","溶岩"]
D28: =SUM(AJ28:AZ28,F28:N28)&"/"&SUM(F28:N28)&"/"&SUM(AJ28:AZ28) -> 0/0/0 | E28: 1 | BG28: {=IF($A28="","", INDEX(CS!$B$1:$B$15026,MATCH($A28,CS!$B:$B,0)+COLUMN(A$1),1))} | BH28: {=IF($A28="","", INDEX(CS!$B$1:$B$15026,MATCH($A28,CS!$B:$B,0)+COLUMN(B$1),1))} | BI28: {=IF($A28="","", INDEX(CS!$B$1:$B$15026,MATCH($A28,CS!$B:$B,0)+COLUMN(C$1),1))} | BJ28: {=IF($A28="","", INDEX(CS!$B$1:$B$15026,MATCH($A28,CS!$B:$B,0)+COLUMN(D$1),1))} | BK28: {=IF($A28="","", INDEX(CS!$B$1:$B$15026,MATCH($A28,CS!$B:$B,0)+COLUMN(E$1),1))} | BL28: {=IF($A28="","", INDEX(CS!$B$1:$B$15026,MATCH($A28,CS!$B:$B,0)+COLUMN(F$1),1))} | BM28: {=IF($A28="","", INDEX(CS!$B$1:$B$15026,MATCH($A28,CS!$B:$B,0)+COLUMN(G$1),1))} | BN28: {=IF($A28="","", INDEX(CS!$B$1:$B$15026,MATCH($A28,CS!$B:$B,0)+COLUMN(H$1),1))} | ... BP28: {=IF($A28="","", INDEX(CS!$B$1:$B$15026,MATCH($A28,CS!$B:$B,0)+COLUMN(J$1),1))}
B29: -=========== 悪魔 ===========- | D29: =SUM(AJ29:AZ29,F29:N29)&"/"&SUM(F29:N29)&"/"&SUM(AJ29:AZ29) -> 0/0/0 | BG29: {=IF($A29="","", INDEX(CS!$B$1:$B$15026,MATCH($A29,CS!$B:$B,0)+COLUMN(A$1),1))} | BH29: {=IF($A29="","", INDEX(CS!$B$1:$B$15026,MATCH($A29,CS!$B:$B,0)+COLUMN(B$1),1))} | BI29: {=IF($A29="","", INDEX(CS!$B$1:$B$15026,MATCH($A29,CS!$B:$B,0)+COLUMN(C$1),1))} | BJ29: {=IF($A29="","", INDEX(CS!$B$1:$B$15026,MATCH($A29,CS!$B:$B,0)+COLUMN(D$1),1))} | BK29: {=IF($A29="","", INDEX(CS!$B$1:$B$15026,MATCH($A29,CS!$B:$B,0)+COLUMN(E$1),1))} | BL29: {=IF($A29="","", INDEX(CS!$B$1:$B$15026,MATCH($A29,CS!$B:$B,0)+COLUMN(F$1),1))} | BM29: {=IF($A29="","", INDEX(CS!$B$1:$B$15026,MATCH($A29,CS!$B:$B,0)+COLUMN(G$1),1))} | BN29: {=IF($A29="","", INDEX(CS!$B$1:$B$15026,MATCH($A29,CS!$B:$B,0)+COLUMN(H$1),1))} | ... BP29: {=IF($A29="","", INDEX(CS!$B$1:$B$15026,MATCH($A29,CS!$B:$B,0)+COLUMN(J$1),1))}
A30: デヴィル | C30: 魔族 | D30: =SUM(AJ30:AZ30,F30:N30)&"/"&SUM(F30:N30)&"/"&SUM(AJ30:AZ30) -> 710/515/195 | E30: 1 | F30: 90 | I30: 80 | J30: 70 | K30: 80 | L30: 60 | M30: 70 | N30: 65 | O30: 170 | P30: -100 | Q30: 10 | R30: 5 | W30: 15 | X30: 15 | AA30: -30 | AB30: 15 | AJ30: 50 | AK30: 50 | AL30: 35 | AM30: 15 | AN30: 0 | AO30: 0 | AP30: 0 | AQ30: 35 | AR30: 35 | AS30: -25 | AT30: -25 | AU30: -25 | AV30: -25 | AW30: 0 | AX30: 0 | AY30: 75 | AZ30: 0 | BA30: 0 | BB30: 100 | BC30: 100 | BD30: 0 | BE30: 0 | BF30: 50 | BG30: {=IF($A30="","", INDEX(CS!$B$1:$B$15026,MATCH($A30,CS!$B:$B,0)+COLUMN(A$1),1))} | BH30: {=IF($A30="","", INDEX(CS!$B$1:$B$15026,MATCH($A30,CS!$B:$B,0)+COLUMN(B$1),1))} -> 邪視 | BI30: {=IF($A30="","", INDEX(CS!$B$1:$B$15026,MATCH($A30,CS!$B:$B,0)+COLUMN(C$1),1))} -> 悪魔の槍 | BJ30: {=IF($A30="","", INDEX(CS!$B$1:$B$15026,MATCH($A30,CS!$B:$B,0)+COLUMN(D$1),1))} | BK30: {=IF($A30="","", INDEX(CS!$B$1:$B$15026,MATCH($A30,CS!$B:$B,0)+COLUMN(E$1),1))} -> 悪魔の槍 | BL30: {=IF($A30="","", INDEX(CS!$B$1:$B$15026,MATCH($A30,CS!$B:$B,0)+COLUMN(F$1),1))} -> 悪の魔力 | BM30: {=IF($A30="","", INDEX(CS!$B$1:$B$15026,MATCH($A30,CS!$B:$B,0)+COLUMN(G$1),1))} -> 悪魔の外皮 | BN30: {=IF($A30="","", INDEX(CS!$B$1:$B$15026,MATCH($A30,CS!$B:$B,0)+COLUMN(H$1),1))} | ... BP30: {=IF($A30="","", INDEX(CS!$B$1:$B$15026,MATCH($A30,CS!$B:$B,0)+COLUMN(J$1),1))} -> 次元の扉 | BV30: 魂 | BW30: 30 | BX30: 0 | BY30: 0 | BZ30: 35 | CA30: 15 | CD30: 2 | CN30: 悪魔 | CO30: ["火山","荒野"] | CP30: ["雪原"]
A31: アークデヴィル | C31: 魔族 | D31: =SUM(AJ31:AZ31,F31:N31)&"/"&SUM(F31:N31)&"/"&SUM(AJ31:AZ31) -> 710/515/195 | E31: 2 | F31: 90 | I31: 80 | J31: 70 | K31: 80 | L31: 60 | M31: 70 | N31: 65 | O31: 170 | P31: -100 | Q31: 10 | R31: 5 | W31: 15 | X31: 15 | AA31: -30 | AB31: 15 | AJ31: 50 | AK31: 50 | AL31: 35 | AM31: 15 | AN31: 0 | AO31: 0 | AP31: 0 | AQ31: 35 | AR31: 35 | AS31: -25 | AT31: -25 | AU31: -25 | AV31: -25 | AW31: 0 | AX31: 0 | AY31: 75 | AZ31: 0 | BA31: 0 | BB31: 100 | BC31: 100 | BD31: 0 | BE31: 0 | BF31: 50 | BG31: {=IF($A31="","", INDEX(CS!$B$1:$B$15026,MATCH($A31,CS!$B:$B,0)+COLUMN(A$1),1))} -> #N/A | BH31: {=IF($A31="","", INDEX(CS!$B$1:$B$15026,MATCH($A31,CS!$B:$B,0)+COLUMN(B$1),1))} -> #N/A | BI31: {=IF($A31="","", INDEX(CS!$B$1:$B$15026,MATCH($A31,CS!$B:$B,0)+COLUMN(C$1),1))} -> #N/A | BJ31: {=IF($A31="","", INDEX(CS!$B$1:$B$15026,MATCH($A31,CS!$B:$B,0)+COLUMN(D$1),1))} -> #N/A | BK31: {=IF($A31="","", INDEX(CS!$B$1:$B$15026,MATCH($A31,CS!$B:$B,0)+COLUMN(E$1),1))} -> #N/A | BL31: {=IF($A31="","", INDEX(CS!$B$1:$B$15026,MATCH($A31,CS!$B:$B,0)+COLUMN(F$1),1))} -> #N/A | BM31: {=IF($A31="","", INDEX(CS!$B$1:$B$15026,MATCH($A31,CS!$B:$B,0)+COLUMN(G$1),1))} -> #N/A | BN31: {=IF($A31="","", INDEX(CS!$B$1:$B$15026,MATCH($A31,CS!$B:$B,0)+COLUMN(H$1),1))} -> #N/A | ... BP31: {=IF($A31="","", INDEX(CS!$B$1:$B$15026,MATCH($A31,CS!$B:$B,0)+COLUMN(J$1),1))} -> #N/A | BQ31: 20 | BR31: デヴィル_10 | BX31: 0 | BY31: 0 | BZ31: 35 | CA31: 15 | CD31: 2 | CN31: 悪魔 | CO31: ["火山","荒野"] | CP31: ["雪原"]
A32: アーチデヴィル | C32: 魔族 | D32: =SUM(AJ32:AZ32,F32:N32)&"/"&SUM(F32:N32)&"/"&SUM(AJ32:AZ32) -> 710/515/195 | E32: 3 | F32: 90 | I32: 80 | J32: 70 | K32: 80 | L32: 60 | M32: 70 | N32: 65 | O32: 170 | P32: -100 | Q32: 10 | R32: 5 | W32: 15 | X32: 15 | AA32: -30 | AB32: 15 | AJ32: 50 | AK32: 50 | AL32: 35 | AM32: 15 | AN32: 0 | AO32: 0 | AP32: 0 | AQ32: 35 | AR32: 35 | AS32: -25 | AT32: -25 | AU32: -25 | AV32: -25 | AW32: 0 | AX32: 0 | AY32: 75 | AZ32: 0 | BA32: 0 | BB32: 100 | BC32: 100 | BD32: 0 | BE32: 0 | BF32: 50 | BG32: {=IF($A32="","", INDEX(CS!$B$1:$B$15026,MATCH($A32,CS!$B:$B,0)+COLUMN(A$1),1))} -> #N/A | BH32: {=IF($A32="","", INDEX(CS!$B$1:$B$15026,MATCH($A32,CS!$B:$B,0)+COLUMN(B$1),1))} -> #N/A | BI32: {=IF($A32="","", INDEX(CS!$B$1:$B$15026,MATCH($A32,CS!$B:$B,0)+COLUMN(C$1),1))} -> #N/A | BJ32: {=IF($A32="","", INDEX(CS!$B$1:$B$15026,MATCH($A32,CS!$B:$B,0)+COLUMN(D$1),1))} -> #N/A | BK32: {=IF($A32="","", INDEX(CS!$B$1:$B$15026,MATCH($A32,CS!$B:$B,0)+COLUMN(E$1),1))} -> #N/A | BL32: {=IF($A32="","", INDEX(CS!$B$1:$B$15026,MATCH($A32,CS!$B:$B,0)+COLUMN(F$1),1))} -> #N/A | BM32: {=IF($A32="","", INDEX(CS!$B$1:$B$15026,MATCH($A32,CS!$B:$B,0)+COLUMN(G$1),1))} -> #N/A | BN32: {=IF($A32="","", INDEX(CS!$B$1:$B$15026,MATCH($A32,CS!$B:$B,0)+COLUMN(H$1),1))} -> #N/A | ... BP32: {=IF($A32="","", INDEX(CS!$B$1:$B$15026,MATCH($A32,CS!$B:$B,0)+COLUMN(J$1),1))} -> #N/A | BQ32: 30 | BR32: アークデヴィル_10 | BX32: 0 | BY32: 0 | BZ32: 35 | CA32: 15 | CD32: 2 | CN32: 悪魔 | CO32: ["火山","荒野"] | CP32: ["雪原"] | CR32: 500
A33: ヘルザーデヴィル | C33: 魔族 | D33: =SUM(AJ33:AZ33,F33:N33)&"/"&SUM(F33:N33)&"/"&SUM(AJ33:AZ33) -> 710/515/195 | E33: 4 | F33: 90 | I33: 80 | J33: 70 | K33: 80 | L33: 60 | M33: 70 | N33: 65 | O33: 170 | P33: -100 | AJ33: 50 | AK33: 50 | AL33: 35 | AM33: 15 | AN33: 0 | AO33: 0 | AP33: 0 | AQ33: 35 | AR33: 35 | AS33: -25 | AT33: -25 | AU33: -25 | AV33: -25 | AW33: 0 | AX33: 0 | AY33: 75 | AZ33: 0 | BA33: 0 | BB33: 100 | BC33: 100 | BD33: 0 | BE33: 0 | BF33: 50 | BQ33: 40 | BR33: アーチデヴィル_10 | BU33: デヴィル派生。性能は基礎デヴィル値を暫定継承。専用スキル・詳細階層は未調整。 | BX33: 0 | BY33: 0 | BZ33: 35 | CA33: 15 | CD33: 2 | CN33: 悪魔 | CO33: ["火山","荒野"] | CP33: ["雪原"] | CR33: 1000
A34: フレイムデヴィル | C34: 魔族 | D34: =SUM(AJ34:AZ34,F34:N34)&"/"&SUM(F34:N34)&"/"&SUM(AJ34:AZ34) -> 710/515/195 | E34: 2 | F34: 90 | I34: 80 | J34: 70 | K34: 80 | L34: 60 | M34: 70 | N34: 65 | O34: 170 | P34: -100 | AJ34: 50 | AK34: 50 | AL34: 35 | AM34: 15 | AN34: 0 | AO34: 0 | AP34: 0 | AQ34: 35 | AR34: 35 | AS34: -25 | AT34: -25 | AU34: -25 | AV34: -25 | AW34: 0 | AX34: 0 | AY34: 75 | AZ34: 0 | BA34: 0 | BB34: 100 | BC34: 100 | BD34: 0 | BE34: 0 | BF34: 50 | BR34: デヴィル_10 | BU34: デヴィル派生。性能は基礎デヴィル値を暫定継承。専用スキル・詳細階層は未調整。 | BX34: 0 | BY34: 0 | BZ34: 35 | CA34: 15 | CD34: 2 | CN34: 悪魔 | CO34: ["火山","荒野"] | CP34: ["雪原"]
A35: ヘルフレイムデヴィル | C35: 魔族 | D35: =SUM(AJ35:AZ35,F35:N35)&"/"&SUM(F35:N35)&"/"&SUM(AJ35:AZ35) -> 710/515/195 | E35: 2 | F35: 90 | I35: 80 | J35: 70 | K35: 80 | L35: 60 | M35: 70 | N35: 65 | O35: 170 | P35: -100 | AJ35: 50 | AK35: 50 | AL35: 35 | AM35: 15 | AN35: 0 | AO35: 0 | AP35: 0 | AQ35: 35 | AR35: 35 | AS35: -25 | AT35: -25 | AU35: -25 | AV35: -25 | AW35: 0 | AX35: 0 | AY35: 75 | AZ35: 0 | BA35: 0 | BB35: 100 | BC35: 100 | BD35: 0 | BE35: 0 | BF35: 50 | BR35: デヴィル_10 | BU35: デヴィル派生。性能は基礎デヴィル値を暫定継承。専用スキル・詳細階層は未調整。 | BX35: 0 | BY35: 0 | BZ35: 35 | CA35: 15 | CD35: 2 | CN35: 悪魔 | CO35: ["火山","荒野"] | CP35: ["雪原"]
A36: ヘルフロストデヴィル | C36: 魔族 | D36: =SUM(AJ36:AZ36,F36:N36)&"/"&SUM(F36:N36)&"/"&SUM(AJ36:AZ36) -> 710/515/195 | E36: 2 | F36: 90 | I36: 80 | J36: 70 | K36: 80 | L36: 60 | M36: 70 | N36: 65 | O36: 170 | P36: -100 | AJ36: 50 | AK36: 50 | AL36: 35 | AM36: 15 | AN36: 0 | AO36: 0 | AP36: 0 | AQ36: 35 | AR36: 35 | AS36: -25 | AT36: -25 | AU36: -25 | AV36: -25 | AW36: 0 | AX36: 0 | AY36: 75 | AZ36: 0 | BA36: 0 | BB36: 100 | BC36: 100 | BD36: 0 | BE36: 0 | BF36: 50 | BR36: デヴィル_10 | BU36: デヴィル派生。性能は基礎デヴィル値を暫定継承。専用スキル・詳細階層は未調整。 | BX36: 0 | BY36: 0 | BZ36: 35 | CA36: 15 | CD36: 2 | CN36: 悪魔 | CO36: ["火山","荒野"] | CP36: ["雪原"]
A37: ブラッドデヴィル | C37: 魔族 | D37: =SUM(AJ37:AZ37,F37:N37)&"/"&SUM(F37:N37)&"/"&SUM(AJ37:AZ37) -> 710/515/195 | E37: 2 | F37: 90 | I37: 80 | J37: 70 | K37: 80 | L37: 60 | M37: 70 | N37: 65 | O37: 170 | P37: -100 | AJ37: 50 | AK37: 50 | AL37: 35 | AM37: 15 | AN37: 0 | AO37: 0 | AP37: 0 | AQ37: 35 | AR37: 35 | AS37: -25 | AT37: -25 | AU37: -25 | AV37: -25 | AW37: 0 | AX37: 0 | AY37: 75 | AZ37: 0 | BA37: 0 | BB37: 100 | BC37: 100 | BD37: 0 | BE37: 0 | BF37: 50 | BR37: デヴィル_10 | BU37: デヴィル派生。性能は基礎デヴィル値を暫定継承。専用スキル・詳細階層は未調整。 | BX37: 0 | BY37: 0 | BZ37: 35 | CA37: 15 | CD37: 2 | CN37: 悪魔 | CO37: ["火山","荒野"] | CP37: ["雪原"]
A38: 武装生成 | C38: 魔族 | D38: =SUM(AJ38:AZ38,F38:N38)&"/"&SUM(F38:N38)&"/"&SUM(AJ38:AZ38) -> 710/515/195 | E38: 2 | F38: 90 | I38: 80 | J38: 70 | K38: 80 | L38: 60 | M38: 70 | N38: 65 | O38: 170 | P38: -100 | AJ38: 50 | AK38: 50 | AL38: 35 | AM38: 15 | AN38: 0 | AO38: 0 | AP38: 0 | AQ38: 35 | AR38: 35 | AS38: -25 | AT38: -25 | AU38: -25 | AV38: -25 | AW38: 0 | AX38: 0 | AY38: 75 | AZ38: 0 | BA38: 0 | BB38: 100 | BC38: 100 | BD38: 0 | BE38: 0 | BF38: 50 | BR38: デヴィル_10 | BU38: デヴィル専用系統。性能は基礎デヴィル値を暫定継承。専用スキル・正式な階層は未調整。 | BX38: 0 | BY38: 0 | BZ38: 35 | CA38: 15 | CD38: 2 | CN38: 悪魔 | CO38: ["火山","荒野"] | CP38: ["雪原"]
A39: 魔眼 | C39: 魔族 | D39: =SUM(AJ39:AZ39,F39:N39)&"/"&SUM(F39:N39)&"/"&SUM(AJ39:AZ39) -> 710/515/195 | E39: 2 | F39: 90 | I39: 80 | J39: 70 | K39: 80 | L39: 60 | M39: 70 | N39: 65 | O39: 170 | P39: -100 | AJ39: 50 | AK39: 50 | AL39: 35 | AM39: 15 | AN39: 0 | AO39: 0 | AP39: 0 | AQ39: 35 | AR39: 35 | AS39: -25 | AT39: -25 | AU39: -25 | AV39: -25 | AW39: 0 | AX39: 0 | AY39: 75 | AZ39: 0 | BA39: 0 | BB39: 100 | BC39: 100 | BD39: 0 | BE39: 0 | BF39: 50 | BR39: デヴィル_10 | BU39: デヴィル専用系統。性能は基礎デヴィル値を暫定継承。専用スキル・正式な階層は未調整。 | BX39: 0 | BY39: 0 | BZ39: 35 | CA39: 15 | CD39: 2 | CN39: 悪魔 | CO39: ["火山","荒野"] | CP39: ["雪原"]
A40: 変身 | C40: 魔族 | D40: =SUM(AJ40:AZ40,F40:N40)&"/"&SUM(F40:N40)&"/"&SUM(AJ40:AZ40) -> 710/515/195 | E40: 2 | F40: 90 | I40: 80 | J40: 70 | K40: 80 | L40: 60 | M40: 70 | N40: 65 | O40: 170 | P40: -100 | AJ40: 50 | AK40: 50 | AL40: 35 | AM40: 15 | AN40: 0 | AO40: 0 | AP40: 0 | AQ40: 35 | AR40: 35 | AS40: -25 | AT40: -25 | AU40: -25 | AV40: -25 | AW40: 0 | AX40: 0 | AY40: 75 | AZ40: 0 | BA40: 0 | BB40: 100 | BC40: 100 | BD40: 0 | BE40: 0 | BF40: 50 | BR40: デヴィル_10 | BU40: デヴィル専用系統。性能は基礎デヴィル値を暫定継承。専用スキル・正式な階層は未調整。 | BX40: 0 | BY40: 0 | BZ40: 35 | CA40: 15 | CD40: 2 | CN40: 悪魔 | CO40: ["火山","荒野"] | CP40: ["雪原"]
A41: 空間操作 | C41: 魔族 | D41: =SUM(AJ41:AZ41,F41:N41)&"/"&SUM(F41:N41)&"/"&SUM(AJ41:AZ41) -> 710/515/195 | E41: 2 | F41: 90 | I41: 80 | J41: 70 | K41: 80 | L41: 60 | M41: 70 | N41: 65 | O41: 170 | P41: -100 | AJ41: 50 | AK41: 50 | AL41: 35 | AM41: 15 | AN41: 0 | AO41: 0 | AP41: 0 | AQ41: 35 | AR41: 35 | AS41: -25 | AT41: -25 | AU41: -25 | AV41: -25 | AW41: 0 | AX41: 0 | AY41: 75 | AZ41: 0 | BA41: 0 | BB41: 100 | BC41: 100 | BD41: 0 | BE41: 0 | BF41: 50 | BR41: デヴィル_10 | BU41: デヴィル専用系統。性能は基礎デヴィル値を暫定継承。専用スキル・正式な階層は未調整。 | BX41: 0 | BY41: 0 | BZ41: 35 | CA41: 15 | CD41: 2 | CN41: 悪魔 | CO41: ["火山","荒野"] | CP41: ["雪原"]
...

Sheet 種族
A1: 種族 | B1: 能力クラス | C1: 使用可 | D1: 旧名称 | E1: 画像 | F1: 概要 | G1: 詳細 | H1: 特徴 | I1: マーカー文字 | J1: マーカー色 | K1: 初期人数 | L1: 高さ | M1: ヒーロー | N1: 軍隊 | O1: 土地 | P1: 設定メモ | Q1: 推奨クラス | R1: 推奨都市特化
A2: 只人 | B2: ヒューマン | C2: TRUE | D2: ["人間","ヒューマン"] | E2: /assets/images/role/人間.webp | F2: 都市運営と前線維持の両面が安定した標準種族。 | G2: 制度適応が高く、どの国家体制でも扱いやすい。初期拡張や内政立ち上げを堅実に進められる。 | H2: ["統治適応","兵站安定","万能型"] | I2: 只 | J2: #3e5d84 | K2: 50 | L2: 0 | M2: 1 | N2: 0.15 | O2: 平地 | R2: 交易都市/農業都市/学術都市
A3: エルフ | B3: エルフ | C3: TRUE | D3: ["森人"] | E3: /assets/images/role/森人.webp | F3: 魔法・索敵に秀でた長命種。 | G3: 森地形と相性が良く、精密運用で真価を発揮する。防衛よりも戦術優位を取り続ける構成向き。 | H3: ["魔術適性","索敵強化","森林親和"] | I3: 森 | J3: #4a7d3c | K3: 50 | L3: 0 | M3: 1 | N3: 0.1 | O3: 森 | Q3: ウィザード/アーチャー/スカウト/ドルイド | R3: 魔法都市/学術都市/神秘都市
A4: ドワーフ | B4: ドワーフ | C4: FALSE | D4: ["土人"] | I4: 土 | J4: #7a5f3a | K4: 50 | L4: 1 | M4: 1 | N4: 0.1 | O4: 洞窟,丘,山 | P4: 表示情報（画像・概要・詳細・特徴）が未設定 | Q4: ファイター/ナイト/ドルイド
A5: 獣人 | B5: ビーストマン | C5: FALSE | D5: ["ビーストマン"] | I5: 獣 | J5: #8a6d2e | K5: 60 | L5: 1 | M5: 0.8 | N5: 0.2 | O5: 平地 | P5: 表示情報（画像・概要・詳細・特徴）が未設定 | Q5: モンク/レンジャー/フェンサー
A6: 竜人 | B6: ドラゴニュート | C6: TRUE | D6: ["ドラゴニュート"] | E6: /assets/images/role/竜人.webp | F6: 範囲攻撃と高い制圧力を持つ高位戦闘種。 | G6: 攻守の基礎値が高く、軍事ルートとの相性が良い。主戦力として扱いやすく、対多数でも崩れにくい。 | H6: ["範囲制圧","高火力","高耐性"] | I6: 竜 | J6: #39687f | K6: 25 | L6: 1 | M6: 1.25 | N6: 0.25 | O6: 丘,山,平地,沼 | Q6: ファイター/ウォーリアー/ガーディアン | R6: 軍事都市/城塞都市
A7: オーガ | B7: オーガ | C7: TRUE | D7: ["大鬼"] | E7: /assets/images/illust/オーガ.webp | F7: 高耐久と打撃力で前線を押し込む巨躯種。 | G7: 初動から強く、接敵後の制圧戦に強い。継戦コストは重いが、局地戦の突破力は全種族でも上位。 | H7: ["高耐久","前線圧力","近接制圧"] | I7: 鬼 | J7: #7f3f2e | K7: 25 | L7: 1 | M7: 0.8 | N7: 0.35 | O7: 丘,平地,森,山 | Q7: ファイター/ウォーリアー/ガーディアン | R7: 軍事都市/城塞都市
A8: 巨人 | B8: ジャイアント | C8: FALSE | D8: ["ジャイアント"] | I8: 巨 | J8: #6b5c4b | K8: 15 | L8: 2 | M8: 1.2 | N8: 0.45 | O8: 丘,平地,山 | P8: 表示情報（画像・概要・詳細・特徴）が未設定
A9: ゴブリン | B9: ゴブリン | C9: TRUE | D9: ["鬼妖"] | E9: /assets/images/illust/ゴブリン.webp | F9: 機動と数で優位を作る群体運用向け種族。 | G9: 単体性能は低いが展開速度が高く、補給線妨害や攪乱が得意。長期戦では構成次第で化ける。 | H9: ["展開速度","攪乱","低コスト運用"] | I9: 妖 | J9: #5f7c3a | K9: 75 | L9: 0 | M9: 0.5 | N9: 0.1 | O9: 丘,森 | Q9: スカウト/アーチャー/ファイター | R9: 軍事都市/交易都市
A10: 悪魔 | B10: デヴィル | C10: TRUE | D10: ["デヴィル"] | E10: /assets/images/role/悪魔.webp | F10: 吸収・圧殺に寄った攻勢特化種族。 | G10: 短期決戦の爆発力が高い。治安や内政の管理負荷は上がるが、戦闘リターンは非常に大きい。 | H10: ["吸収戦闘","攻勢特化","高リスク高リターン"] | I10: 魔 | J10: #6a2f4f | K10: 10 | L10: 3 | M10: 1.5 | N10: 0.6 | O10: 山,森,湖 | Q10: ウィザード/ファイター/スカウト | R10: 魔法都市/軍事都市/神秘都市
A11: 天使 | B11: エンジェル | C11: TRUE | D11: ["エンジェル"] | E11: /assets/images/role/天使.webp | F11: 支援と維持戦に優れた加護系種族。 | G11: 部隊全体の安定性を上げる効果が多く、長期戦で有利。信仰系スキルや統治との噛み合わせが良い。 | H11: ["全体支援","持久戦","信仰適性"] | I11: 天 | J11: #5c6fa2 | K11: 15 | L11: 3 | M11: 1.5 | N11: 0.6 | O11: 火山,山,丘,洞窟 | Q11: クレリック/ナイト/パラディン | R11: 信仰都市/城塞都市
A12: ヴァンパイア | B12: ヴァンパイア | C12: TRUE | D12: ["吸血鬼"] | E12: /assets/images/role/吸血鬼.webp | F12: 継戦吸収型の技巧種族。 | G12: 削り合いに強く、戦線維持能力が高い。瞬間火力よりも、戦闘テンポの主導権を握る運用向き。 | H12: ["自己回復","持久戦","夜戦適性"] | I12: 吸 | J12: #662f4a | K12: 10 | L12: 3 | M12: 1.5 | N12: 0.6 | O12: 洞窟,森,渓谷 | P12: 高さ未設定 | Q12: ウィザード/スカウト/レンジャー | R12: 軍事都市/城塞都市/死者の都
C13: FALSE
C14: FALSE
C15: FALSE
C16: FALSE
C17: FALSE
C18: FALSE
C19: FALSE
C20: FALSE
C21: FALSE
C22: FALSE
C23: FALSE
C24: FALSE
... C1000: FALSE

Sheet 用語辞書
A1: 追加効果 | B1: 説明 | D1: 技能名 | E1: 説明 | G1: 範囲タイプ | H1: 説明 | I1: 処理タイプ
A2: 連鎖 | B2: 対象から近くの別対象へ順に連鎖して効果が及ぶ | D2: 指揮 | E2: 部隊への命令効率を高める。士気上昇量やバフ効果量が増加し、部隊スキルの性能が向上する。 | G2: 単体 | H2: 指定した1体のみを対象にする | I2: single
A3: 能力値回復 | B3: 対象の能力値（攻撃・防御・魔力・精神・速度・命中など）を回復する | D3: 威圧 | E3: 騙すを併合。敵やNPCに心理的圧力を与える。敵士気低下や怯え付与、会話時の威圧成功率が上昇する。 | G3: 直線 | H3: 指定方向へ一直線上の対象を貫通して攻撃する | I3: line
A4: AP回復 | B4: 対象のAPを回復する | D4: 看破 | E4: 知識を含む。敵能力・弱点・嘘・罠・アイテムの性質を見破る。不意打ち耐性や情報取得能力が向上する。 | G4: 扇 | H4: 自分前方に扇形範囲で攻撃する | I4: fan
A5: AP増加 | B5: 対象の最大APまたは現在AP上限を一時的に増加させる | D5: 早業 | E5: 軽業を併合。攻撃速度や回避率が上昇し、移動系スキルの消費が軽減される。連撃性能が向上する。 | G5: 円 | H5: 指定地点を中心とした円形範囲を攻撃する | I5: circle
A6: APダメージ | B6: 対象のAPを減少させる | D6: 技術 | E6: 装置操作・罠設置・修理・制作補助能力。戦闘中のトラップ性能や道具効果が向上する。 | G6: 周囲 | H6: 自分を中心とした円形範囲を攻撃する。間に対象がいると後ろには当たらない | I6: around
A7: HPダメージ | B7: 対象のHPにダメージを与える | D7: 隠密 | E7: 発見されにくくなる。奇襲成功率や離脱成功率が上昇し、不意打ち時の威力が増加する。 | G7: 前方 | H7: 自分前方の矩形（長方形）範囲を攻撃する。 | I7: front
A8: 攻撃ダメージ | B8: 対象の攻撃値を一時的に減少させる | D8: 索敵 | E8: 敵や資源を発見しやすくなる。遭遇率制御、罠発見、危険察知能力が向上する。 | G8: ライン | H8: 2か所を指定しその間を攻撃 | I8: line
A9: 防御ダメージ | B9: 対象の防御値を一時的に減少させる | D9: 農業 | E9: 穀物・家畜など農業生産効率を上昇させる。災害による収穫減少を軽減する。 | G9: 全体 | H9: 対象陣営全体に効果が及ぶ | I9: all
A10: 魔力ダメージ | B10: 対象の魔力を一時的に減少させる | D10: 林業 | E10: 木材資源の取得量と森林管理効率を上昇させる。森林枯渇速度を軽減する。
A11: 精神ダメージ | B11: 対象の精神を一時的に減少させる | D11: 漁業 | E11: 水域資源の取得量を上昇させる。食料安定度に補正を与える。 | G11: 味方 | I11: all
A12: 速度ダメージ | B12: 対象の速度を一時的に減少させる | D12: 工業 | E12: 加工・生産効率を上昇させる。装備や施設の生産速度が向上する。 | G12: 敵 | I12: all
A13: 命中ダメージ | B13: 対象の命中を一時的に減少させる | D13: 統治 | E13: 都市安定度や治安を向上させる。反乱発生率を低下させ、維持費効率を改善する。 | G13: 全て | I13: all
A14: 技能ダメージ | B14: 対象の技能値を一時的に減少させる | D14: 交渉 | E14: 交易価格や外交成功率を上昇させる。条約締結や取引条件が有利になる。 | G14: 自身以外 | I14: all
A15: 炎上 | B15: 毎ターンHPダメージを受ける状態 | D15: 魔術 | E15: 魔法スキルの威力や成功率を向上させる。魔法道具の作成ができるようになり、防衛力が上昇する。 | G15: 放射 | H15: 使用者の前方へ扇状に放射する | I15: fan
A16: 凍結 | B16: 速度とAPと防御にダメージ | D16: 信仰 | E16: 宗教効果や祝福系能力を強化する。回復速度が上昇、アンデッドの出現を抑制できる。 | G16: 散弾 | H16: 指定方向の複数マスへ散開して攻撃する | I16: fan
A17: 帯電 | B17: 速度とAPと怯みにダメージ | G17: 縦 | H17: 指定方向へ縦一列を攻撃する | I17: line
A18: 腐蝕 | B18: 毎ターンHPダメージ＋防御にダメージ | G18: 爆発 | H18: 指定地点を中心に円形範囲を攻撃する | I18: circle
A19: 気絶 | B19: 一定時間行動不能になる状態 | G19: 炸裂 | H19: 指定地点を中心に炸裂し周囲へ効果を与える | I19: circle
A20: 遮断 | B20: 自身の後ろに攻撃が届かなくなる | G20: 奥1 | H20: 着弾点と、使用者から見て着弾点のさらに奥1マスを対象にする（計2マス）
A21: 恐怖 | B21: 攻撃・命中・士気などが低下する状態 | G21: 奥2 | H21: 着弾点と、その奥へ一直線に2マスを対象にする（計3マス）
A22: 混乱 | B22: 行動が指定したスキル、近くに攻撃、自分に攻撃、このターンAPがなくなるのどれかになる。 | G22: 後方2 | H22: 着弾点と、使用者から見て着弾点の奥側に隣接する左右2マスを対象にする（計3マス）
A23: 魅了 | B23: 一時的に敵対行動ができなくなる、または味方扱いになる状態 | G23: 横2 | H23: 着弾点と、進行方向に対して左右の隣接2マスを対象にする（計3マス）
A24: 吸血 | B24: 与えた出血ダメージ分をHPとして回復する | G24: 小扇 | H24: 着弾点を先端として奥側へ広がる小型の扇形範囲。着弾点を含む4マスを基本とする
A25: 吸収 | B25: 与えたダメージや効果の一部を自分の能力値に変換する | G25: 半径1 | H25: 着弾点を中心に隣接6マスを含む範囲（計7マス） | I25: circle
A26: 反射 | B26: 受けたダメージの一部を攻撃者へ返す
A27: 障壁 | B27: 追加HPを得て、なくなるまで追加効果を受けなくなる
A28: 時間停止 | B28: 一定時間対象の行動や時間経過を停止させる
A30: 吹き飛ばし | B30: 対象を後方へ移動させる
A31: 引き寄せ | B31: 対象を自分の方へ移動させる
A32: 位置交換 | B32: 対象と位置を入れ替える
A33: 転倒 | B33: 移動不可＋回避低下
A34: 浮遊 | B34: 地形効果を無視する
A35: 固定 | B35: 指定位置から移動不可
A37: 復活 | B37: 戦闘不能から復帰
A38: 不死 | B38: HP0でも一定ターン生存
A39: 封印 | B39: 特定属性無効化
... A70: 壁生成 | B70: 高さ+1マスの壁を作る。耐久値は魔法の値

Sheet 地形
A1: 地形 | B1: 詳細 | C1: モンスター危険度 | D1: 開拓難易度 | E1: 移動コスト | F1: 移動条件 | G1: 穀物 | H1: 野菜 | I1: 肉 | J1: 魚 | K1: 木材 | L1: 黒木 | M1: 特木 | N1: 石材 | O1: 鉄 | P1: 銀鉄 | Q1: 青金鋼 | R1: 赤黒鋼 | S1: 金 | T1: 銀 | U1: 宝石 | V1: 台風 | W1: 竜巻 | X1: 吹雪 | Y1: 噴火 | Z1: 砂嵐 | AA1: 洪水 | AB1: 地震 | AC1: 雷嵐 | AD1: HP | AE1: MP | AF1: ST | AG1: 攻撃 | AH1: 防御 | AI1: 魔力 | AJ1: 精神 | AK1: 速度 | AL1: 命中 | AM1: SIZ | AN1: 指揮 | AO1: 威圧 | AP1: 看破 | AQ1: 早業 | AR1: 技術 | AS1: 隠密 | AT1: 索敵 | AU1: 農業 | AV1: 林業 | AW1: 漁業 | AX1: 工業 | AY1: 統治 | AZ1: 交渉 | BA1: 魔術 | BB1: 信仰 | BD1: 保有可能人数 | BE1: 浄化 | BF1: 穢れ | BG1: 回復 | BH1: ヒーロー | BI1: 軍隊 | BJ1: 生成対象 | BK1: 生成順 | BL1: 生成色 | BM1: 生成重み | BN1: 生成略称 | BO1: 勢力配置区分 | BP1: 休火山候補率 | BQ1: 別名 | BR1: ターンダメージ最大HP率 | BS1: ターンダメージ耐性 | BT1: 変換レイヤー | BU1: 発見研究区分 | BV1: 必要発見研究Lv | BW1: 危険地帯設定
A2: 平地 | B2: 移動コスト1。基準マス。都市建設可。生産補正なし。視界良好。 | C2: 0.2 | D2: 1 | E2: 1 | F2: - | G2: 60 | H2: 40 | I2: 20 | J2: 0 | K2: 25 | L2: 0 | M2: 0 | N2: 25 | O2: 10 | P2: 0 | Q2: 0 | R2: 0 | S2: 0 | T2: 0 | U2: 0 | V2: 0 | W2: 0.1 | X2: 0 | Y2: 0 | Z2: 0 | AA2: 0.05 | AB2: -0.05 | AC2: 0.05 | BJ2: =TRUE() -> TRUE | BK2: 1 | BL2: #b6cc71 | BM2: 26 | BN2: 平 | BO2: 基本 | BT2: 基本
A3: 森 | B3: 移動コスト2。木材資源+。隠密+35 過剰採取で平地化。 | C3: 0.6 | D3: 3 | E3: 2 | F3: - | G3: 25 | H3: 60 | I3: 35 | J3: 0 | K3: 100 | L3: 0 | M3: 0 | N3: 25 | O3: 0 | P3: 0 | Q3: 0 | R3: 0 | S3: 0 | T3: 0 | U3: 0 | V3: -0.05 | W3: -0.05 | X3: 0.05 | Y3: 0 | Z3: 0 | AA3: 0.05 | AB3: 0.05 | AC3: 0.1 | AK3: -10 | AL3: -5 | AS3: 35 | BB3: 15 | BJ3: =TRUE() -> TRUE | BK3: 3 | BL3: #7fa56a | BM3: 18 | BN3: 森 | BO3: 基本 | BT3: 基本
A4: 丘陵 | B4: 移動コスト2。鉱石資源+中。都市建設可。 | C4: 0.5 | D4: 3 | E4: 2 | F4: - | G4: 20 | H4: 20 | I4: 60 | J4: 10 | K4: 40 | L4: 0 | M4: 0 | N4: 100 | O4: 80 | P4: 0 | Q4: 0 | R4: 0 | S4: 10 | T4: 0 | U4: 0 | V4: -0.05 | W4: -0.05 | X4: 0.1 | Y4: 0.1 | Z4: 0 | AA4: -0.05 | AB4: 0.15 | AC4: 0.1 | AS4: -10 | BJ4: =TRUE() -> TRUE | BK4: 4 | BL4: #a49367 | BM4: 12 | BN4: 丘 | BO4: 基本 | BQ4: 丘
A5: 山岳 | B5: 通常移動不可（飛行/特殊のみ可）。鉱石資源+大。都市建設不可。 | C5: 0.8 | D5: 5 | E5: 2 | F5: - | G5: 10 | H5: 10 | I5: 20 | J5: 10 | K5: 30 | L5: 0 | M5: 0 | N5: 150 | O5: 200 | P5: 0 | Q5: 0 | R5: 0 | S5: 30 | T5: 0 | U5: 0 | V5: -0.1 | W5: -0.05 | X5: 0.15 | Y5: 0.2 | Z5: 0 | AA5: -0.05 | AB5: 0.2 | AC5: 0.1 | AK5: -15 | AL5: -10 | BB5: 25 | BJ5: =TRUE() -> TRUE | BK5: 5 | BL5: #8b847d | BM5: 10 | BN5: 山 | BO5: 基本 | BP5: 0.2 | BQ5: 山
A6: 湖 | B6: 水上ユニットのみ移動可。食料+中。防御補正なし。 | C6: 0.5 | D6: 2 | E6: 1 | F6: 遊泳 | G6: 10 | H6: 10 | I6: 0 | J6: 90 | K6: 0 | L6: 0 | M6: 0 | N6: 0 | O6: 35 | P6: 0 | Q6: 0 | R6: 0 | S6: 8 | T6: 0 | U6: 0 | V6: 0.1 | W6: -0.1 | X6: -0.05 | Y6: 0 | Z6: 0 | AA6: 0.2 | AB6: -0.1 | AC6: 0.05 | BB6: 35 | BJ6: =TRUE() -> TRUE | BK6: 9 | BL6: #6ea5d1 | BM6: 8 | BN6: 湖 | BO6: 基本
A7: 河川 | B7: 移動コスト2（橋で1）。農業+20%。都市隣接で成長+。 | C7: 0.4 | D7: 2 | E7: 1 | F7: - | G7: 20 | H7: 15 | I7: 5 | J7: 35 | K7: 0 | L7: 0 | M7: 0 | N7: 0 | O7: 0 | P7: 0 | Q7: 0 | R7: 0 | S7: 5 | T7: 0 | U7: 0 | V7: 0.2 | W7: -0.05 | X7: -0.05 | Y7: 0 | Z7: 0 | AA7: 0.2 | AB7: -0.05 | AC7: 0.05 | BJ7: =TRUE() -> TRUE | BK7: 8 | BL7: #78aed8 | BM7: 10 | BN7: 川 | BO7: 基本 | BQ7: 河
A8: 大河 | B8: 移動コスト4（橋で1）水上ユニットはペナルティなし | C8: 0.4 | D8: 2 | E8: 4 | F8: - | G8: 25 | H8: 35 | I8: 10 | J8: 60 | K8: 0 | L8: 0 | M8: 0 | N8: 0 | O8: 0 | P8: 0 | Q8: 0 | R8: 0 | S8: 5 | T8: 0 | U8: 0 | V8: 0.2 | W8: -0.05 | X8: -0.05 | Y8: 0 | Z8: 0 | AA8: 0.2 | AB8: -0.05 | AC8: 0.05
A9: 海 | B9: 水上ユニットのみ移動可。交易+。港設置可。嵐イベント発生。 | C9: 0.75 | D9: 4 | E9: 2 | F9: 遊泳 | G9: 10 | H9: 10 | I9: 0 | J9: 110 | K9: 0 | L9: 0 | M9: 0 | N9: 0 | O9: 35 | P9: 0 | Q9: 0 | R9: 0 | S9: 20 | T9: 0 | U9: 0 | V9: 0.35 | W9: -0.1 | X9: -0.05 | Y9: 0 | Z9: 0 | AA9: 0.35 | AB9: -0.1 | AC9: 0.05 | BJ9: =TRUE() -> TRUE | BK9: 10 | BL9: #4f88ba | BM9: 7 | BN9: 海
A10: 荒野 | B10: 移動コスト1。基準マス。都市建設可。生産補正なし。視界良好。 | C10: 0.3 | D10: 1 | E10: 1 | F10: - | G10: 15 | H10: 15 | I10: 20 | J10: 0 | K10: 0 | L10: 0 | M10: 0 | N10: 100 | O10: 45 | P10: 0 | Q10: 0 | R10: 0 | S10: 5 | T10: 0 | U10: 0 | V10: 0 | W10: 0.1 | X10: 0 | Y10: 0 | Z10: 0.1 | AA10: 0 | AB10: 0.1 | AC10: 0 | BJ10: =TRUE() -> TRUE | BK10: 2 | BL10: #d9c98b | BM10: 12 | BN10: 荒 | BO10: 基本 | BQ10: 荒 | BT10: 基本
A11: 砂漠 | B11: 移動コスト2。生産-20%。水源があれば都市可。特殊資源あり。 | C11: 0.5 | D11: 4 | E11: 2 | F11: - | G11: 10 | H11: 10 | I11: 10 | J11: 0 | K11: 0 | L11: 0 | M11: 0 | N11: 50 | O11: 0 | P11: 0 | Q11: 0 | R11: 0 | S11: 30 | T11: 0 | U11: 0 | V11: -0.05 | W11: 0.05 | X11: -0.1 | Y11: 0 | Z11: 0.3 | AA11: -0.05 | AB11: 0.05 | AC11: 0.05 | AK11: -10 | AL11: -10 | AS11: -10 | BJ11: =TRUE() -> TRUE | BK11: 11 | BL11: #d8be76 | BM11: 7 | BN11: 砂 | BO11: 基本 | BT11: 基本
A12: 沼地 | B12: 移動コスト3。防御+5%。毒耐性判定発生。農業不可。 | C12: 0.65 | D12: 4 | E12: 3 | F12: - | G12: 10 | H12: 15 | I12: 20 | J12: 50 | K12: 20 | L12: 0 | M12: 0 | N12: 5 | O12: 0 | P12: 0 | Q12: 0 | R12: 0 | S12: 0 | T12: 0 | U12: 0 | V12: 0.1 | W12: 0 | X12: 0 | Y12: 0 | Z12: 0 | AA12: 0.3 | AB12: 0 | AC12: 0.1 | AK12: -25 | AL12: -15 | AS12: 10 | BO12: 特殊 | BQ12: 沼 | BT12: 特殊
A13: 湿地 | B13: 移動コスト3。防御+5%。毒耐性判定発生。農業不可。 | C13: 0.65 | D13: 4 | E13: 3 | F13: - | G13: 45 | H13: 30 | I13: 20 | J13: 30 | K13: 20 | L13: 0 | M13: 0 | N13: 5 | O13: 0 | P13: 0 | Q13: 0 | R13: 0 | S13: 0 | T13: 0 | U13: 0 | V13: 0.1 | W13: 0 | X13: 0 | Y13: 0 | Z13: 0 | AA13: 0.3 | AB13: 0 | AC13: 0.1 | AK13: -25 | AL13: -15 | AS13: 10 | BT13: 特殊
A14: 峡谷 | B14: 通常通行不可（橋必須）。防御+20%。地形要塞。 | C14: 0.7 | D14: 5 | E14: 2 | F14: 飛行 | G14: 5 | H14: 5 | I14: 15 | J14: 0 | K14: 5 | L14: 0 | M14: 0 | N14: 160 | O14: 120 | P14: 0 | Q14: 0 | R14: 0 | S14: 20 | T14: 0 | U14: 0 | V14: -0.1 | W14: -0.05 | X14: 0.05 | Y14: 0.1 | Z14: 0.05 | AA14: -0.2 | AB14: 0.3 | AC14: 0.05 | AS14: 15 | BO14: 特殊 | BQ14: 渓谷
A15: 洞窟 | B15: 地下扱い。視界制限。特殊資源+。地上ユニット制限あり。 | C15: 0.9 | D15: 6 | E15: 1 | F15: - | G15: 0 | H15: 0 | I15: 10 | J15: 0 | K15: 0 | L15: 0 | M15: 0 | N15: 80 | O15: 150 | P15: 0 | Q15: 0 | R15: 0 | S15: 40 | T15: 0 | U15: 0 | V15: 0 | W15: 0 | X15: 0 | Y15: 0 | Z15: 0 | AA15: -0.3 | AB15: 0.25 | AC15: 0 | AS15: 45 | BO15: 特殊 | BQ15: 洞 | BU15: 地下探索 | BV15: 1
A16: 雪原 | B16: 移動コスト2。生産-10%。寒冷耐性でペナルティ無効。 | C16: 0.65 | D16: 3 | E16: 1 | F16: - | G16: 12 | H16: 10 | I16: 35 | J16: 5 | K16: 8 | L16: 0 | M16: 0 | N16: 70 | O16: 50 | P16: 0 | Q16: 0 | R16: 0 | S16: 8 | T16: 0 | U16: 0 | V16: -0.05 | W16: 0.05 | X16: 0.25 | Y16: 0 | Z16: 0 | AA16: -0.05 | AB16: 0.1 | AC16: 0.1 | AK16: -15 | AL16: -10 | BJ16: =TRUE() -> TRUE | BK16: 6 | BL16: #cfdbe8 | BM16: 6 | BN16: 雪 | BO16: 基本 | BQ16: 雪 | BT16: 基本
A17: 火山 | B17: 都市不可。鉱石+大。噴火イベントあり。防御+15%。 | C17: 0.95 | D17: 6 | E17: 2 | F17: - | G17: 2 | H17: 3 | I17: 10 | J17: 0 | K17: 0 | L17: 0 | M17: 0 | N17: 180 | O17: 80 | P17: 0 | Q17: 0 | R17: 0 | S17: 80 | T17: 0 | U17: 0 | V17: 0 | W17: 0 | X17: 0 | Y17: 0.4 | Z17: 0.1 | AA17: -0.3 | AB17: 0.3 | AC17: 0.15 | BB17: 50 | BJ17: =TRUE() -> TRUE | BK17: 7 | BL17: #7e4f45 | BM17: 4 | BN17: 火 | BO17: 基本
A18: 溶岩 | B18: 通常移動不可。耐熱ユニットのみ可。ダメージ地形。 | C18: 0.9 | D18: 3 | E18: 2 | F18: 耐熱|炎耐性:100 | G18: -50 | H18: -50 | I18: -50 | J18: -50 | K18: -75 | L18: 0 | M18: 0 | N18: 25 | O18: 25 | P18: 0 | Q18: 0 | R18: 0 | S18: 10 | T18: 0 | U18: 0 | V18: 0 | W18: 0 | X18: 0 | Y18: 0 | Z18: 0 | AA18: 0 | AB18: 0 | AC18: 0 | AK18: -30 | AL18: -30 | BR18: 0.1 | BS18: 炎耐性
A19: 死の霧 | B19: アンデッドが発生するようになる霧。 そのマスで倒されたキャラや出現する敵にアンデッドが付与されることがある。 | C19: 0.9 | D19: 4 | E19: 0 | F19: - | G19: -50 | H19: -50 | I19: -50 | J19: -50 | K19: -75 | L19: 0 | M19: 0 | N19: 0 | O19: 0 | P19: 0 | Q19: 0 | R19: 0 | S19: 0 | T19: 0 | U19: 0 | V19: 0 | W19: 0 | X19: 0 | Y19: 0 | Z19: 0 | AA19: 0 | AB19: 0 | AC19: 0 | AL19: -15 | AS19: 20 | BF19: 50 | BT19: 特殊
A21: 薬草の群生地 | G21: 15 | H21: 15 | BE21: 5 | BG21: 10 | BT21: 特殊 | BU21: 生態調査 | BV21: 1
A22: 金山 | C22: 0.3 | S22: 40 | BU22: 地質調査 | BV22: 1
A23: 銀鉱脈 | C23: 0.15 | T23: 0 | BU23: 地質調査 | BV23: 1
A24: 宝石脈 | C24: 0.15 | U24: 0 | BU24: 地質調査 | BV24: 2
A25: 水脈 | C25: 0.1 | G25: 20 | J25: 10 | AA25: 0.25 | AB25: 0.25 | BG25: 5
A26: 戦場後 | G26: -15 | H26: -15 | I26: -15 | J26: -15 | K26: -15 | L26: 0 | M26: 0 | N26: -15 | O26: -15 | P26: 0 | Q26: 0 | R26: 0 | S26: -15 | T26: 0 | BF26: 20
A29: 道路1 | B29: 移動コスト-1（最低1）。建設コスト低。交易+小。 | C29: 0 | D29: 2 | G29: -10 | H29: -10 | I29: -10 | J29: -10 | K29: -10 | L29: 0 | M29: 0 | N29: -10 | O29: -10 | P29: 0 | Q29: 0 | R29: 0 | S29: -10 | T29: 0 | U29: 0 | V29: 0 | W29: 0 | X29: 0 | Y29: 0 | Z29: 0 | AA29: 0 | AB29: 0 | AC29: 0 | AS29: -30
A30: 道路2 | B30: 移動コスト1固定。交易+中。軍移動速度+。 | C30: 0 | D30: 3 | G30: -10 | H30: -10 | I30: -10 | J30: -10 | K30: -10 | L30: 0 | M30: 0 | N30: -10 | O30: -10 | P30: 0 | Q30: 0 | R30: 0 | S30: -10 | T30: 0 | U30: 0 | V30: 0 | W30: 0 | X30: 0 | Y30: 0 | Z30: 0 | AA30: 0 | AB30: 0 | AC30: 0 | AS30: -30
A31: 道路3 | B31: 移動コスト1固定。交易+大。補給効率+。軍事道路扱い。 | C31: 0 | D31: 4 | G31: -10 | H31: -10 | I31: -10 | J31: -10 | K31: -10 | L31: 0 | M31: 0 | N31: -10 | O31: -10 | P31: 0 | Q31: 0 | R31: 0 | S31: -10 | T31: 0 | U31: 0 | V31: 0 | W31: 0 | X31: 0 | Y31: 0 | Z31: 0 | AA31: 0 | AB31: 0 | AC31: 0 | AS31: -30
A32: 太陽の山 | B32: 太陽の光を宿す霊峰。勝利対象土地として使用する。
A33: 黄昏の樹 | B33: 黄昏の気配をまとった巨樹。勝利対象土地として使用する。
A34: 星の火口 | B34: 星光を宿す火口。勝利対象土地として使用する。
A35: 宇宙の海 | B35: 宇宙を映す海域。勝利対象土地として使用する。
A36: 酸の沼 | B36: 常設危険地帯。沼地,洞窟に重ねる環境レイヤー。 | BJ36: FALSE | BM36: 0 | BT36: 環境 | BV36: 0 | BW36: {"disasterId":"危険地帯:酸の沼","regionSize":12,"chance":0.18,"radius":1,"terrains":["沼地"],"underground":true,"color":"#A4C742"}
A37: 毒沼 | B37: 常設危険地帯。湿地,森に重ねる環境レイヤー。 | BJ37: FALSE | BM37: 0 | BT37: 環境 | BV37: 0 | BW37: {"disasterId":"危険地帯:毒沼","regionSize":12,"chance":0.18,"radius":1,"terrains":["湿地","森","森林"],"interiorForest":true,"color":"#6C9A3A"}
A38: 常霧の谷 | B38: 常設危険地帯。峡谷,湖に重ねる環境レイヤー。 | BJ38: FALSE | BM38: 0 | BT38: 環境 | BV38: 0 | BW38: {"disasterId":"危険地帯:常霧の谷","regionSize":12,"chance":0.18,"radius":1,"terrains":["峡谷","渓谷"],"near":["湖","河川"],"color":"#DCE7EB"}
A39: 噴気地帯 | B39: 常設危険地帯。火山に重ねる環境レイヤー。 | BJ39: FALSE | BM39: 0 | BT39: 環境 | BV39: 0 | BW39: {"disasterId":"危険地帯:噴気地帯","regionSize":12,"chance":0.18,"radius":1,"near":["火山","溶岩"],"color":"#CFB879"}
A40: 極寒地帯 | B40: 常設危険地帯。雪原,山岳に重ねる環境レイヤー。 | BJ40: FALSE | BM40: 0 | BT40: 環境 | BV40: 0 | BW40: {"disasterId":"危険地帯:極寒地帯","regionSize":12,"chance":0.18,"radius":1,"terrains":["雪原","雪山","氷原"],"minimumHeight":5,"color":"#83D9FA"}
A41: 瘴気地帯 | B41: 常設危険地帯。廃墟,洞窟に重ねる環境レイヤー。 | BJ41: FALSE | BM41: 0 | BT41: 環境 | BV41: 0 | BW41: {"disasterId":"危険地帯:瘴気地帯","regionSize":12,"chance":0.18,"radius":1,"terrains":["廃墟","遺跡","洞窟"],"underground":true,"deep":true,"color":"#A6BD48"}

Sheet 出現敵
A1: 出現地形 | B1: 種族名 | C1: チェック用 | D1: 好戦的 | E1: 種族 | F1: サブクラス | G1: Lv_Min | H1: Lv_Max | I1: 出現数 | J1: 備考 | K1: 武器 | L1: 副武器 | M1: 胴 | N1: 頭 | O1: 足 | P1: 装飾1 | Q1: 装飾2 | R1: 画像 | S1: 巣 | W1: ID | X1: 画像ファイル | Y1: 画像番号 | Z1: 画像サイズ連動 | AA1: 出現形態 | AB1: 集団数_Min | AC1: 集団数_Max | AD1: 編成人数 | AE1: 最低気温 | AF1: 最高気温 | AG1: 出現しやすい天候
A2: 1 | B2: 2 | C2: 3 | D2: 4 | E2: 5 | F2: 6 | G2: 7 | H2: 8 | I2: 9 | J2: 10 | K2: 11 | L2: 12 | M2: 13 | N2: 14 | O2: 15 | P2: 16 | Q2: 17 | R2: 18
A3: 平地 | B3: ホーク | C3: =LET( _xlpm.dOK,COUNTIF('クラス'!A:A,E3)>0, _xlpm.eOK,COUNTIF('クラス'!A:A,F3)>0, IF(_xlpm.dOK,"○","×") & IF(_xlpm.eOK,"○","×") ) -> ○× | D3: TRUE | E3: ホーク | G3: 2 | H3: 6 | R3: イーグル | S3: =IFERROR(VLOOKUP(B3,$U:$V,2,FALSE),"") -> 鳥系生物の巣 | U3: ホーク | V3: 鳥系生物の巣 | W3: 出現敵:平地:ホーク:5:8 | X3: ホーク・スネーク_ユニット集.webp | Y3: 1 | AD3: 1
A4: 平地 | B4: スネーク | C4: =LET( _xlpm.dOK,COUNTIF('クラス'!A:A,E4)>0, _xlpm.eOK,COUNTIF('クラス'!A:A,F4)>0, IF(_xlpm.dOK,"○","×") & IF(_xlpm.eOK,"○","×") ) -> ○× | E4: スネーク | G4: 1 | H4: 5 | R4: スネーク | S4: =IFERROR(VLOOKUP(B4,$U:$V,2,FALSE),"") -> 肉食生物の巣 | U4: スネーク | V4: 肉食生物の巣 | W4: 出現敵:平地:スネーク:4:7 | X4: ホーク・スネーク_ユニット集.webp | Y4: 7 | AD4: 1 | AE4: 0 | AF4: 45 | AG4: 雨/雷雨
A5: 平地 | B5: アンケグ | C5: =LET( _xlpm.dOK,COUNTIF('クラス'!A:A,E5)>0, _xlpm.eOK,COUNTIF('クラス'!A:A,F5)>0, IF(_xlpm.dOK,"○","×") & IF(_xlpm.eOK,"○","×") ) -> ×× | G5: 5 | H5: 10 | S5: =IFERROR(VLOOKUP(B5,$U:$V,2,FALSE),"") -> 虫系の巣 | U5: アンケグ | V5: 虫系の巣 | W5: 出現敵:平地:アンケグ:: | X5: アンケグ・スコーピオン_ユニット集.webp | Y5: 1 | AD5: 1
A6: 平地 | B6: ブレット | C6: =LET( _xlpm.dOK,COUNTIF('クラス'!A:A,E6)>0, _xlpm.eOK,COUNTIF('クラス'!A:A,F6)>0, IF(_xlpm.dOK,"○","×") & IF(_xlpm.eOK,"○","×") ) -> ×× | S6: =IFERROR(VLOOKUP(B6,$U:$V,2,FALSE),"") -> 地中生物の巣 | U6: ブレット | V6: 地中生物の巣 | W6: 出現敵:平地:ブレット:: | AD6: 1
A7: 平地 | B7: マンティコア | C7: =LET( _xlpm.dOK,COUNTIF('クラス'!A:A,E7)>0, _xlpm.eOK,COUNTIF('クラス'!A:A,F7)>0, IF(_xlpm.dOK,"○","×") & IF(_xlpm.eOK,"○","×") ) -> ○○ | D7: TRUE | E7: タイガー | F7: ホーク | G7: 5 | H7: 15 | R7: マンティコア | S7: =IFERROR(VLOOKUP(B7,$U:$V,2,FALSE),"") -> 肉食生物の巣 | U7: マンティコア | V7: 肉食生物の巣 | W7: 出現敵:平地:マンティコア:12:15 | X7: 魔獣_ユニット集2.webp | Y7: 1 | AD7: 1
A8: 平地 | B8: ディスプレイサービースト | C8: =LET( _xlpm.dOK,COUNTIF('クラス'!A:A,E8)>0, _xlpm.eOK,COUNTIF('クラス'!A:A,F8)>0, IF(_xlpm.dOK,"○","×") & IF(_xlpm.eOK,"○","×") ) -> ○○ | E8: ウルフ | F8: ゴースト | G8: 5 | H8: 15 | R8: ディスプレイサービースト | S8: =IFERROR(VLOOKUP(B8,$U:$V,2,FALSE),"") -> 肉食生物の巣 | U8: ディスプレイサービースト | V8: 肉食生物の巣 | W8: 出現敵:平地:ディスプレイサービースト:12:15 | X8: 魔獣_ユニット集2.webp | Y8: 6 | AD8: 1
A9: 平地 | B9: ワイバーン | C9: =LET( _xlpm.dOK,COUNTIF('クラス'!A:A,E9)>0, _xlpm.eOK,COUNTIF('クラス'!A:A,F9)>0, IF(_xlpm.dOK,"○","×") & IF(_xlpm.eOK,"○","×") ) -> ○× | D9: TRUE | E9: ワイバーン | G9: 15 | H9: 20 | R9: ワイバーン | S9: =IFERROR(VLOOKUP(B9,$U:$V,2,FALSE),"") -> 飛竜の巣 | U9: ワイバーン | V9: 飛竜の巣 | W9: 出現敵:平地:ワイバーン:15:20 | AD9: 1
C10: =LET( _xlpm.dOK,COUNTIF('クラス'!A:A,E10)>0, _xlpm.eOK,COUNTIF('クラス'!A:A,F10)>0, IF(_xlpm.dOK,"○","×") & IF(_xlpm.eOK,"○","×") ) -> ×× | S10: =IFERROR(VLOOKUP(B10,$U:$V,2,FALSE),"")
A11: 荒野 | B11: ウルフ | C11: =LET( _xlpm.dOK,COUNTIF('クラス'!A:A,E11)>0, _xlpm.eOK,COUNTIF('クラス'!A:A,F11)>0, IF(_xlpm.dOK,"○","×") & IF(_xlpm.eOK,"○","×") ) -> ○× | D11: TRUE | E11: ウルフ | G11: 3 | H11: 7 | R11: ファングウルフ | S11: =IFERROR(VLOOKUP(B11,$U:$V,2,FALSE),"") -> 肉食生物の巣 | U11: ウルフ | V11: 肉食生物の巣 | W11: 出現敵:荒野:ウルフ:5:8 | X11: 魔獣_ユニット集1.webp | Y11: 3 | AD11: 1
A12: 荒野 | B12: スネーク | C12: =LET( _xlpm.dOK,COUNTIF('クラス'!A:A,E12)>0, _xlpm.eOK,COUNTIF('クラス'!A:A,F12)>0, IF(_xlpm.dOK,"○","×") & IF(_xlpm.eOK,"○","×") ) -> ○× | E12: スネーク | G12: 1 | H12: 5 | R12: スネーク | S12: =IFERROR(VLOOKUP(B12,$U:$V,2,FALSE),"") -> 肉食生物の巣 | U12: スネーク | V12: 肉食生物の巣 | W12: 出現敵:荒野:スネーク:4:7 | X12: ホーク・スネーク_ユニット集.webp | Y12: 7 | AD12: 1 | AE12: 0 | AF12: 45 | AG12: 雨/雷雨
A13: 荒野 | B13: クロコダイル | C13: =LET( _xlpm.dOK,COUNTIF('クラス'!A:A,E13)>0, _xlpm.eOK,COUNTIF('クラス'!A:A,F13)>0, IF(_xlpm.dOK,"○","×") & IF(_xlpm.eOK,"○","×") ) -> ○× | D13: TRUE | E13: クロコダイル | G13: 4 | H13: 8 | S13: =IFERROR(VLOOKUP(B13,$U:$V,2,FALSE),"") -> 肉食生物の巣 | U13: クロコダイル | V13: 肉食生物の巣 | W13: 出現敵:荒野:クロコダイル:7:9 | X13: クロコダイル・タイガー_ユニット集.webp | Y13: 1 | AD13: 1 | AE13: 0 | AF13: 45 | AG13: 雨/雷雨
A14: 荒野 | B14: デザートワーム | C14: =LET( _xlpm.dOK,COUNTIF('クラス'!A:A,E14)>0, _xlpm.eOK,COUNTIF('クラス'!A:A,F14)>0, IF(_xlpm.dOK,"○","×") & IF(_xlpm.eOK,"○","×") ) -> ○× | E14: スネーク | G14: 5 | H14: 10 | S14: =IFERROR(VLOOKUP(B14,$U:$V,2,FALSE),"") -> 地中生物の巣 | U14: デザートワーム | V14: 地中生物の巣 | W14: 出現敵:荒野:デザートワーム:8:12 | X14: ワーム_ユニット集.webp | Y14: 2 | AD14: 1 | AE14: 0 | AF14: 45 | AG14: 雨/雷雨
