Workbook

Sheet クラス
A1: 名前 | B1: ルビ | C1: 種類 | D1: 合計 | E1: Lv | F1: HP | G1: 攻撃 | H1: 防御 | I1: 魔力 | J1: 精神 | K1: 速度 | L1: 命中 | M1: SIZ | N1: 物理耐性 | O1: 魔法耐性 | P1: 炎耐性 | Q1: 氷耐性 | R1: 雷耐性 | S1: 毒耐性 | T1: 光耐性 | U1: 闇耐性 | V1: 精神耐性 | W1: 怯み耐性 | X1: 出血耐性 | Y1: 拘束耐性 | Z1: 幻覚耐性 | AA1: Cr率耐性 | AB1: Cr威力耐性 | AC1: 指揮 | AD1: 威圧 | AE1: 看破 | AF1: 早業 | AG1: 技術 | AH1: 隠密 | AI1: 索敵 | AJ1: 農業 | AK1: 林業 | AL1: 漁業 | AM1: 工業 | AN1: 統治 | AO1: 交渉 | AP1: 魔法技術 | AQ1: 信仰 | AR1: Skill1 | AS1: Skill2 | AT1: Skill3 | AU1: Skill4 | AV1: Skill5 | AW1: Skill6 | AX1: Skill7 | AY1: Skill8 | AZ1: Skill9 | BA1: Skill10 | BB1: 条件Lv | BC1: 条件_1 | BD1: Lv_1 | BE1: 条件_2 | BF1: Lv_2 | BG1: 条件_3 | BH1: Lv_3 | BI1: 条件_4 | BJ1: Lv_4
N2: 50 | O2: 51 | P2: 52 | Q2: 53 | R2: 54 | S2: 55 | T2: 56 | U2: 57 | V2: 58 | W2: 59 | X2: 60 | Y2: 61 | Z2: 62 | AA2: 63 | AB2: 64 | AC2: 指揮 | AD2: 部隊への命令効率を高める。士気上昇量やバフ効果量が増加し、部隊スキルの性能が向上する。
AC3: 威圧 | AD3: 騙すを併合。敵やNPCに心理的圧力を与える。敵士気低下や怯え付与、会話時の威圧成功率が上昇する。
AC4: 看破 | AD4: 知識を含む。敵能力・弱点・嘘・罠・アイテムの性質を見破る。不意打ち耐性や情報取得能力が向上する。
AC5: 早業 | AD5: 軽業を併合。攻撃速度や回避率が上昇し、移動系スキルの消費が軽減される。連撃性能が向上する。
AC6: 技術 | AD6: 装置操作・罠設置・修理・制作補助能力。戦闘中のトラップ性能や道具効果が向上する。
AC7: 隠密 | AD7: 発見されにくくなる。奇襲成功率や離脱成功率が上昇し、不意打ち時の威力が増加する。
AC8: 索敵 | AD8: 敵や資源を発見しやすくなる。遭遇率制御、罠発見、危険察知能力が向上する。
AC9: 農業 | AD9: 穀物・家畜など農業生産効率を上昇させる。災害による収穫減少を軽減する。
AC10: 林業 | AD10: 木材資源の取得量と森林管理効率を上昇させる。森林枯渇速度を軽減する。
AC11: 漁業 | AD11: 水域資源の取得量を上昇させる。食料安定度に補正を与える。
AC12: 工業 | AD12: 加工・生産効率を上昇させる。装備や施設の生産速度が向上する。
AC13: 統治 | AD13: 都市安定度や治安を向上させる。反乱発生率を低下させ、維持費効率を改善する。
AC14: 交渉 | AD14: 交易価格や外交成功率を上昇させる。条約締結や取引条件が有利になる。
... AC16: 信仰 | AD16: 宗教効果や祝福系能力を強化する。士気回復や精神耐性補正が向上する。
A18: ファイター | B18: 戦士 | C18: 職業 | D18: =SUM(AC18:AQ18,F18:L18)&"/"&SUM(F18:L18)&"/"&SUM(AC18:AQ18) -> 710/460/250 | E18: 1 | F18: 85 | G18: 90 | H18: 80 | I18: 25 | J18: 50 | K18: 55 | L18: 75 | AC18: 75 | AD18: 50 | AE18: 25 | AF18: 25 | AG18: 25 | AI18: 25 | AN18: 25
A19: ナイト | B19: 騎士 | C19: 職業 | D19: =SUM(AC19:AQ19,F19:L19)&"/"&SUM(F19:L19)&"/"&SUM(AC19:AQ19) -> 710/460/250 | E19: 1 | F19: 85 | G19: 80 | H19: 90 | I19: 25 | J19: 55 | K19: 50 | L19: 75 | AC19: 100 | AE19: 25 | AF19: 25 | AG19: 25 | AI19: 25 | AN19: 50
A20: フェンサー | B20: 軽戦士 | C20: 職業 | D20: =SUM(AC20:AQ20,F20:L20)&"/"&SUM(F20:L20)&"/"&SUM(AC20:AQ20) -> 710/460/250 | E20: 1 | F20: 85 | G20: 80 | H20: 55 | I20: 25 | J20: 50 | K20: 90 | L20: 75 | AC20: 50 | AD20: 50 | AE20: 25 | AF20: 50 | AG20: 25 | AI20: 25 | AN20: 25
C21: 職業 | D21: =SUM(AC21:AQ21,F21:L21)&"/"&SUM(F21:L21)&"/"&SUM(AC21:AQ21) -> 0/0/0 | E21: 1
A22: シーフ | B22: 盗賊 | C22: 職業 | D22: =SUM(AC22:AQ22,F22:L22)&"/"&SUM(F22:L22)&"/"&SUM(AC22:AQ22) -> 710/445/265 | E22: 1 | F22: 75 | G22: 75 | H22: 50 | I22: 25 | J22: 50 | K22: 85 | L22: 85 | AD22: 25 | AF22: 50 | AG22: 25 | AH22: 90 | AI22: 75
A23: レンジャー | B23: 狩人 | C23: 職業 | D23: =SUM(AC23:AQ23,F23:L23)&"/"&SUM(F23:L23)&"/"&SUM(AC23:AQ23) -> 710/460/250 | E23: 1 | F23: 75 | G23: 75 | H23: 75 | I23: 25 | J23: 50 | K23: 75 | L23: 85 | AF23: 50 | AG23: 35 | AH23: 75 | AI23: 90
A24: スカウト | B24: 密偵 | C24: 職業 | D24: =SUM(AC24:AQ24,F24:L24)&"/"&SUM(F24:L24)&"/"&SUM(AC24:AQ24) -> 710/445/265 | E24: 1 | F24: 75 | G24: 75 | H24: 50 | I24: 25 | J24: 50 | K24: 85 | L24: 85 | AF24: 50 | AG24: 65 | AH24: 75 | AI24: 75
C25: 職業 | D25: =SUM(AC25:AQ25,F25:L25)&"/"&SUM(F25:L25)&"/"&SUM(AC25:AQ25) -> 0/0/0 | E25: 1
A26: ウィザード | B26: 魔導士 | C26: 職業 | D26: =SUM(AC26:AQ26,F26:L26)&"/"&SUM(F26:L26)&"/"&SUM(AC26:AQ26) -> 710/470/240 | E26: 1 | F26: 60 | G26: 50 | H26: 55 | I26: 90 | J26: 90 | K26: 50 | L26: 75 | AE26: 90 | AN26: 50 | AP26: 100
A27: エレメンタラー | B27: 精霊師 | C27: 職業 | D27: =SUM(AC27:AQ27,F27:L27)&"/"&SUM(F27:L27)&"/"&SUM(AC27:AQ27) -> 710/465/245 | E27: 1 | F27: 60 | G27: 50 | H27: 55 | I27: 85 | J27: 90 | K27: 50 | L27: 75 | AE27: 75 | AF27: 50 | AG27: 20 | AP27: 100
A28: アルケミスト | B28: 錬金術師 | C28: 職業 | D28: =SUM(AC28:AQ28,F28:L28)&"/"&SUM(F28:L28)&"/"&SUM(AC28:AQ28) -> 710/465/245 | E28: 1 | F28: 65 | G28: 55 | H28: 65 | I28: 85 | J28: 70 | K28: 50 | L28: 75 | AE28: 50 | AG28: 95 | AP28: 100
C29: 職業 | D29: =SUM(AC29:AQ29,F29:L29)&"/"&SUM(F29:L29)&"/"&SUM(AC29:AQ29) -> 0/0/0 | E29: 1
A30: クレリック | B30: 神官 | C30: 職業 | D30: =SUM(AC30:AQ30,F30:L30)&"/"&SUM(F30:L30)&"/"&SUM(AC30:AQ30) -> 710/485/225 | E30: 1 | F30: 75 | G30: 70 | H30: 70 | I30: 75 | J30: 70 | K30: 50 | L30: 75 | AE30: 75 | AN30: 50 | AQ30: 100
A31: パラディン | B31: 聖騎士 | C31: 職業 | D31: =SUM(AC31:AQ31,F31:L31)&"/"&SUM(F31:L31)&"/"&SUM(AC31:AQ31) -> 710/485/225 | E31: 1 | F31: 85 | G31: 70 | H31: 85 | I31: 55 | J31: 60 | K31: 55 | L31: 75 | AC31: 50 | AE31: 50 | AN31: 50 | AQ31: 75
A32: ドルイド | B32: 森司祭 | C32: 職業 | D32: =SUM(AC32:AQ32,F32:L32)&"/"&SUM(F32:L32)&"/"&SUM(AC32:AQ32) -> 710/485/225 | E32: 1 | F32: 75 | G32: 65 | H32: 65 | I32: 85 | J32: 70 | K32: 50 | L32: 75 | AE32: 75 | AF32: 25 | AG32: 25 | AI32: 50 | AQ32: 50
C33: 職業 | D33: =SUM(AC33:AQ33,F33:L33)&"/"&SUM(F33:L33)&"/"&SUM(AC33:AQ33) -> 0/0/0 | E33: 1
A34: ヒューマン | C34: 人族 | D34: =SUM(AC34:AQ34,F34:L34)&"/"&SUM(F34:L34)&"/"&SUM(AC34:AQ34) -> 775/460/315 | E34: 1 | F34: 75 | G34: 70 | H34: 70 | I34: 25 | J34: 70 | K34: 70 | L34: 80 | M34: 170 | AC34: 35 | AD34: 35 | AE34: 35 | AF34: 35 | AG34: 35 | AH34: 35 | AI34: 35 | AN34: 35 | AO34: 35
A35: エルフ | C35: 人族 | D35: =SUM(AC35:AQ35,F35:L35)&"/"&SUM(F35:L35)&"/"&SUM(AC35:AQ35) -> 775/460/315 | E35: 1 | F35: 65 | G35: 65 | H35: 70 | I35: 25 | J35: 70 | K35: 85 | L35: 80 | M35: 170 | AC35: 35 | AE35: 35 | AF35: 35 | AH35: 35 | AI35: 35 | AJ35: 35 | AK35: 35 | AN35: 35 | AQ35: 35
A36: ドワーフ | C36: 人族 | D36: =SUM(AC36:AQ36,F36:L36)&"/"&SUM(F36:L36)&"/"&SUM(AC36:AQ36) -> 775/460/315 | E36: 1 | F36: 85 | G36: 80 | H36: 80 | I36: 25 | J36: 60 | K36: 50 | L36: 80 | M36: 140 | AC36: 35 | AD36: 35 | AG36: 35 | AH36: 35 | AI36: 35 | AM36: 35 | AN36: 35 | AO36: 35 | AP36: 35
D37: =SUM(AC37:AQ37,F37:L37)&"/"&SUM(F37:L37)&"/"&SUM(AC37:AQ37) -> 0/0/0
A38: ビーストマン | C38: 亜人 | D38: =SUM(AC38:AQ38,F38:L38)&"/"&SUM(F38:L38)&"/"&SUM(AC38:AQ38) -> 710/490/220 | E38: 1 | F38: 85 | G38: 85 | H38: 65 | I38: 35 | J38: 50 | K38: 100 | L38: 70 | V38: -20 | W38: 10 | Y38: 10 | AD38: 50 | AF38: 50 | AH38: 70 | AI38: 50
A39: ドラゴニュート | C39: 亜人 | D39: =SUM(AC39:AQ39,F39:L39)&"/"&SUM(F39:L39)&"/"&SUM(AC39:AQ39) -> 710/490/220 | E39: 1 | F39: 90 | G39: 90 | H39: 75 | I39: 35 | J39: 70 | K39: 55 | L39: 75 | M39: 170 | N39: 5 | O39: 5 | W39: 15 | Z39: -15 | AD39: 75 | AE39: 45 | AF39: 25 | AI39: 50 | AP39: 25
A40: オーガ | C40: 亜人 | D40: =SUM(AC40:AQ40,F40:L40)&"/"&SUM(F40:L40)&"/"&SUM(AC40:AQ40) -> 710/490/220 | E40: 1 | F40: 105 | G40: 105 | H40: 65 | I40: 55 | J40: 45 | K40: 55 | L40: 60 | M40: 300 | P40: 10 | V40: -15 | W40: 15 | Z40: -15 | AD40: 125 | AE40: 25 | AF40: -25 | AG40: -25 | AH40: 25 | AI40: 25 | AN40: 15 | AO40: 15 | AP40: 40
A41: ジャイアント | C41: 亜人 | D41: =SUM(AC41:AQ41,F41:L41)&"/"&SUM(F41:L41)&"/"&SUM(AC41:AQ41) -> 710/490/220 | E41: 1 | F41: 90 | G41: 90 | H41: 70 | I41: 25 | J41: 70 | K41: 70 | L41: 75 | M41: 550 | AC41: 50 | AD41: 50 | AF41: 25 | AG41: 35 | AN41: 35 | AP41: 25
A42: ゴブリン | C42: 亜人 | D42: =SUM(AC42:AQ42,F42:L42)&"/"&SUM(F42:L42)&"/"&SUM(AC42:AQ42) -> 710/490/220 | E42: 1 | F42: 90 | G42: 90 | H42: 70 | I42: 25 | J42: 55 | K42: 85 | L42: 75 | M42: 100 | S42: 15 | V42: -15 | AC42: 25 | AD42: -25 | AF42: 70 | AG42: 50 | AH42: 75 | AI42: 75 | AN42: -25 | AO42: -25
...

Sheet 説明
A1: 技能名 | B1: 説明
A2: 指揮 | B2: 部隊への命令効率を高める。士気上昇量やバフ効果量が増加し、部隊スキルの性能が向上する。
A3: 威圧 | B3: 騙すを併合。敵やNPCに心理的圧力を与える。敵士気低下や怯え付与、会話時の威圧成功率が上昇する。
A4: 看破 | B4: 知識を含む。敵能力・弱点・嘘・罠・アイテムの性質を見破る。不意打ち耐性や情報取得能力が向上する。
A5: 早業 | B5: 軽業を併合。攻撃速度や回避率が上昇し、移動系スキルの消費が軽減される。連撃性能が向上する。
A6: 技術 | B6: 装置操作・罠設置・修理・制作補助能力。戦闘中のトラップ性能や道具効果が向上する。
A7: 隠密 | B7: 発見されにくくなる。奇襲成功率や離脱成功率が上昇し、不意打ち時の威力が増加する。
A8: 索敵 | B8: 敵や資源を発見しやすくなる。遭遇率制御、罠発見、危険察知能力が向上する。
A9: 農業 | B9: 穀物・家畜など農業生産効率を上昇させる。災害による収穫減少を軽減する。
A10: 林業 | B10: 木材資源の取得量と森林管理効率を上昇させる。森林枯渇速度を軽減する。
A11: 漁業 | B11: 水域資源の取得量を上昇させる。食料安定度に補正を与える。
A12: 工業 | B12: 加工・生産効率を上昇させる。装備や施設の生産速度が向上する。
... A16: 信仰 | B16: 宗教効果や祝福系能力を強化する。士気回復や精神耐性補正が向上する。

Sheet スキル作成
A1: Lv | B1: スキル名 | C1: ルビ | D1: 系統 | E1: 行動 | F1: HP消費 | G1: AP消費 | H1: 効果 | I1: 説明 | J1: 説明2 | K1: 取得条件 | M1: ダブり確認 | N1: 全確認 | O1: 戦闘ルール | P1: 盾装備でデメリットは威力が下がる、軽減値が増える。 | Q1: モンク シーフ レンジャー スカウト ウィザード アルケミスト イリュージョニスト エレメント・マスター クレリック ビショップ プリースト パラディン ゴブリン オーガ トレント インプ エンジェル ソードマスター スピアマスター ブロウマスター シールドマスター ソードセイント スピアセイント ブロウセイント シールドセイント
B2: 1:初級 1 2:下級 23 3:中級 34 4:上級 56 5:下級神 7 6:中級神 89 7:上級神 10 | C2: 35 55 75 95 115 145 175 攻撃追加+1 攻撃回数:2 2倍加 など | D2: 条件 条件系統 | I2: 範囲について 単体,全体,縦,ライン 前後ろ縦を選択してダメージ,周囲(同じ列のみ) 効果に「連鎖」があると周囲に50%ダメージ | J2: 1.突破 1.無詠唱 2.拡大 2.二重 2.持続 | K2: 3.魔法強化 3.射程 4倍速 4.魔法極強化 4.三重 | M2: 回復:35 魔力105~210 10.5~21 | N2: 回復:115 魔力565~1130 34.5~69 | T2: 0.3
B3: 微5~10 小11~20 中21~35 大36~50 極51~ | C3: 〇〇の接続 で魔法取得 〇〇魔法強化 | I3: 攻撃手段:魔法 特殊:攻撃 | K3: 属性: ロール: 技能: スキル:|
L6: =IF(OR(COUNTIF(クラス!$A$1:$A$1020, $B6),$B6="",COUNTIF(スキル一覧!$A$1:$A$3500, $B6)), "", "存在しない") | M6: =IF(COUNTIF($B$1:$C5, $B6), "", "存在しない") -> 存在しない | N6: =IF(AND(A6<>"",L6="存在しない",M6="存在しない"),IF(COUNTIF([1]クラス!$A$1:$A$1000, $B6),"",TRUE),"")
C7: ------------基本職 ------------ | L7: =IF(OR(COUNTIF(クラス!$A$1:$A$1020, $B7),$B7="",COUNTIF(スキル一覧!$A$1:$A$3500, $B7)), "", "存在しない") | M7: =IF(COUNTIF($B$1:$C6, $B7), "", "存在しない") -> 存在しない | N7: =IF(AND(A7<>"",L7="存在しない",M7="存在しない"),IF(COUNTIF([1]クラス!$A$1:$A$1000, $B7),"",TRUE),"")
B8: ファイター | C8: 戦士 | D8: 系統 | E8: スキルタイプ | F8: HP消費 | G8: AP消費 | H8: 効果 | I8: 説明 | J8: 説明2 | L8: =IF(OR(COUNTIF(クラス!$A$1:$A$1020, $B8),$B8="",COUNTIF(スキル一覧!$A$1:$A$3500, $B8)), "", "存在しない") | M8: =IF(COUNTIF($B$1:$C7, $B8), "", "存在しない") -> 存在しない | N8: =IF(AND(A8<>"",L8="存在しない",M8="存在しない"),IF(COUNTIF([1]クラス!$A$1:$A$1000, $B8),"",TRUE),"")
A9: 1 | L9: =IF(OR(COUNTIF(クラス!$A$1:$A$1020, $B9),$B9="",COUNTIF(スキル一覧!$A$1:$A$3500, $B9)), "", "存在しない") | M9: =IF(COUNTIF($B$1:$C8, $B9), "", "存在しない") -> 存在しない | N9: =IF(AND(A9<>"",L9="存在しない",M9="存在しない"),IF(COUNTIF([1]クラス!$A$1:$A$1000, $B9),"",TRUE),"")
A10: 2 | B10: 闘気撃 | C10: オーラ・ストライク | E10: A | G10: 60 | H10: 攻撃手段:武器 物理+25 判定:攻撃 | L10: =IF(OR(COUNTIF(クラス!$A$1:$A$1020, $B10),$B10="",COUNTIF(スキル一覧!$A$1:$A$3500, $B10)), "", "存在しない") -> 存在しない | M10: =IF(COUNTIF($B$1:$C9, $B10), "", "存在しない") -> 存在しない | N10: =IF(AND(A10<>"",L10="存在しない",M10="存在しない"),IF(COUNTIF([1]クラス!$A$1:$A$1000, $B10),"",TRUE),"") -> TRUE
A11: 3 | B11: 武器の扱い | E11: P | H11: 攻撃手段:武器 命中+10 | L11: =IF(OR(COUNTIF(クラス!$A$1:$A$1020, $B11),$B11="",COUNTIF(スキル一覧!$A$1:$A$3500, $B11)), "", "存在しない") -> 存在しない | M11: =IF(COUNTIF($B$1:$C10, $B11), "", "存在しない") -> 存在しない | N11: =IF(AND(A11<>"",L11="存在しない",M11="存在しない"),IF(COUNTIF([1]クラス!$A$1:$A$1000, $B11),"",TRUE),"") -> TRUE
A12: 4 | L12: =IF(OR(COUNTIF(クラス!$A$1:$A$1020, $B12),$B12="",COUNTIF(スキル一覧!$A$1:$A$3500, $B12)), "", "存在しない") | M12: =IF(COUNTIF($B$1:$C11, $B12), "", "存在しない") -> 存在しない | N12: =IF(AND(A12<>"",L12="存在しない",M12="存在しない"),IF(COUNTIF([1]クラス!$A$1:$A$1000, $B12),"",TRUE),"")
A13: 5 | B13: 闘気守 | C13: オーラ・ガード | E13: A | G13: 50 | H13: 攻撃手段:武器 ガード+25 判定:防御 | L13: =IF(OR(COUNTIF(クラス!$A$1:$A$1020, $B13),$B13="",COUNTIF(スキル一覧!$A$1:$A$3500, $B13)), "", "存在しない") -> 存在しない | M13: =IF(COUNTIF($B$1:$C12, $B13), "", "存在しない") -> 存在しない | N13: =IF(AND(A13<>"",L13="存在しない",M13="存在しない"),IF(COUNTIF([1]クラス!$A$1:$A$1000, $B13),"",TRUE),"") -> TRUE
A14: 6 | E14: P | L14: =IF(OR(COUNTIF(クラス!$A$1:$A$1020, $B14),$B14="",COUNTIF(スキル一覧!$A$1:$A$3500, $B14)), "", "存在しない") | M14: =IF(COUNTIF($B$1:$C13, $B14), "", "存在しない") -> 存在しない | N14: =IF(AND(A14<>"",L14="存在しない",M14="存在しない"),IF(COUNTIF([1]クラス!$A$1:$A$1000, $B14),"",TRUE),"")
A15: 7 | L15: =IF(OR(COUNTIF(クラス!$A$1:$A$1020, $B15),$B15="",COUNTIF(スキル一覧!$A$1:$A$3500, $B15)), "", "存在しない") | M15: =IF(COUNTIF($B$1:$C14, $B15), "", "存在しない") -> 存在しない | N15: =IF(AND(A15<>"",L15="存在しない",M15="存在しない"),IF(COUNTIF([1]クラス!$A$1:$A$1000, $B15),"",TRUE),"")
A16: 8 | B16: 雄叫び | C16: ロアー | E16: A | G16: 40 | H16: 効果時間4t 攻撃+15 精神耐性+10 | L16: =IF(OR(COUNTIF(クラス!$A$1:$A$1020, $B16),$B16="",COUNTIF(スキル一覧!$A$1:$A$3500, $B16)), "", "存在しない") -> 存在しない | M16: =IF(COUNTIF($B$1:$C15, $B16), "", "存在しない") -> 存在しない | N16: =IF(AND(A16<>"",L16="存在しない",M16="存在しない"),IF(COUNTIF([1]クラス!$A$1:$A$1000, $B16),"",TRUE),"") -> TRUE
A17: 9 | B17: 武器の攻め | E17: P | H17: 攻撃手段:武器 物理+2 命中+5 | L17: =IF(OR(COUNTIF(クラス!$A$1:$A$1020, $B17),$B17="",COUNTIF(スキル一覧!$A$1:$A$3500, $B17)), "", "存在しない") -> 存在しない | M17: =IF(COUNTIF($B$1:$C16, $B17), "", "存在しない") -> 存在しない | N17: =IF(AND(A17<>"",L17="存在しない",M17="存在しない"),IF(COUNTIF([1]クラス!$A$1:$A$1000, $B17),"",TRUE),"") -> TRUE
A18: 10 | B18: 一閃撃 | C18: ブランデッシュ | E18: A | G18: 60 | H18: 攻撃手段:武器 物理+15 命中+25 判定:攻撃 | L18: =IF(OR(COUNTIF(クラス!$A$1:$A$1020, $B18),$B18="",COUNTIF(スキル一覧!$A$1:$A$3500, $B18)), "", "存在しない") -> 存在しない | M18: =IF(COUNTIF($B$1:$C17, $B18), "", "存在しない") -> 存在しない | N18: =IF(AND(A18<>"",L18="存在しない",M18="存在しない"),IF(COUNTIF([1]クラス!$A$1:$A$1000, $B18),"",TRUE),"") -> TRUE
L19: =IF(OR(COUNTIF(クラス!$A$1:$A$1020, $B19),$B19="",COUNTIF(スキル一覧!$A$1:$A$3500, $B19)), "", "存在しない") | M19: =IF(COUNTIF($B$1:$C18, $B19), "", "存在しない") -> 存在しない | N19: =IF(AND(A19<>"",L19="存在しない",M19="存在しない"),IF(COUNTIF([1]クラス!$A$1:$A$1000, $B19),"",TRUE),"")
L20: =IF(OR(COUNTIF(クラス!$A$1:$A$1020, $B20),$B20="",COUNTIF(スキル一覧!$A$1:$A$3500, $B20)), "", "存在しない") | M20: =IF(COUNTIF($B$1:$C19, $B20), "", "存在しない") -> 存在しない | N20: =IF(AND(A20<>"",L20="存在しない",M20="存在しない"),IF(COUNTIF([1]クラス!$A$1:$A$1000, $B20),"",TRUE),"")
B21: ナイト | L21: =IF(OR(COUNTIF(クラス!$A$1:$A$1020, $B21),$B21="",COUNTIF(スキル一覧!$A$1:$A$3500, $B21)), "", "存在しない") | M21: =IF(COUNTIF($B$1:$C20, $B21), "", "存在しない") -> 存在しない | N21: =IF(AND(A21<>"",L21="存在しない",M21="存在しない"),IF(COUNTIF([1]クラス!$A$1:$A$1000, $B21),"",TRUE),"")
A22: 1 | L22: =IF(OR(COUNTIF(クラス!$A$1:$A$1020, $B22),$B22="",COUNTIF(スキル一覧!$A$1:$A$3500, $B22)), "", "存在しない") | M22: =IF(COUNTIF($B$1:$C21, $B22), "", "存在しない") -> 存在しない | N22: =IF(AND(A22<>"",L22="存在しない",M22="存在しない"),IF(COUNTIF([1]クラス!$A$1:$A$1000, $B22),"",TRUE),"")
A23: 2 | B23: 闘気守 | C23: オーラ・ガード | E23: A | G23: 60 | H23: 攻撃手段:武器 物理+25 判定:攻撃 | L23: =IF(OR(COUNTIF(クラス!$A$1:$A$1020, $B23),$B23="",COUNTIF(スキル一覧!$A$1:$A$3500, $B23)), "", "存在しない") -> 存在しない | M23: =IF(COUNTIF($B$1:$C22, $B23), "", "存在しない") | N23: =IF(AND(A23<>"",L23="存在しない",M23="存在しない"),IF(COUNTIF([1]クラス!$A$1:$A$1000, $B23),"",TRUE),"")
A24: 3 | B24: 武器の扱い | E24: P | H24: 攻撃手段:武器 命中+10 | L24: =IF(OR(COUNTIF(クラス!$A$1:$A$1020, $B24),$B24="",COUNTIF(スキル一覧!$A$1:$A$3500, $B24)), "", "存在しない") -> 存在しない | M24: =IF(COUNTIF($B$1:$C23, $B24), "", "存在しない") | N24: =IF(AND(A24<>"",L24="存在しない",M24="存在しない"),IF(COUNTIF([1]クラス!$A$1:$A$1000, $B24),"",TRUE),"")
A25: 4 | L25: =IF(OR(COUNTIF(クラス!$A$1:$A$1020, $B25),$B25="",COUNTIF(スキル一覧!$A$1:$A$3500, $B25)), "", "存在しない") | M25: =IF(COUNTIF($B$1:$C24, $B25), "", "存在しない") -> 存在しない | N25: =IF(AND(A25<>"",L25="存在しない",M25="存在しない"),IF(COUNTIF([1]クラス!$A$1:$A$1000, $B25),"",TRUE),"")
A26: 5 | B26: 闘気撃 | C26: オーラ・ストライク | E26: A | G26: 50 | H26: 攻撃手段:武器 ガード+25 判定:防御 | L26: =IF(OR(COUNTIF(クラス!$A$1:$A$1020, $B26),$B26="",COUNTIF(スキル一覧!$A$1:$A$3500, $B26)), "", "存在しない") -> 存在しない | M26: =IF(COUNTIF($B$1:$C25, $B26), "", "存在しない") | N26: =IF(AND(A26<>"",L26="存在しない",M26="存在しない"),IF(COUNTIF([1]クラス!$A$1:$A$1000, $B26),"",TRUE),"")
A27: 6 | B27: 反撃 | E27: P | H27: 条件:ガード時 | L27: =IF(OR(COUNTIF(クラス!$A$1:$A$1020, $B27),$B27="",COUNTIF(スキル一覧!$A$1:$A$3500, $B27)), "", "存在しない") -> 存在しない | M27: =IF(COUNTIF($B$1:$C26, $B27), "", "存在しない") -> 存在しない | N27: =IF(AND(A27<>"",L27="存在しない",M27="存在しない"),IF(COUNTIF([1]クラス!$A$1:$A$1000, $B27),"",TRUE),"") -> TRUE
A28: 7 | L28: =IF(OR(COUNTIF(クラス!$A$1:$A$1020, $B28),$B28="",COUNTIF(スキル一覧!$A$1:$A$3500, $B28)), "", "存在しない") | M28: =IF(COUNTIF($B$1:$C27, $B28), "", "存在しない") -> 存在しない | N28: =IF(AND(A28<>"",L28="存在しない",M28="存在しない"),IF(COUNTIF([1]クラス!$A$1:$A$1000, $B28),"",TRUE),"")
A29: 8 | B29: 雄叫び | C29: ロアー | E29: A | G29: 40 | H29: 効果時間4t 攻撃+15 精神耐性+10 | L29: =IF(OR(COUNTIF(クラス!$A$1:$A$1020, $B29),$B29="",COUNTIF(スキル一覧!$A$1:$A$3500, $B29)), "", "存在しない") -> 存在しない | M29: =IF(COUNTIF($B$1:$C28, $B29), "", "存在しない") | N29: =IF(AND(A29<>"",L29="存在しない",M29="存在しない"),IF(COUNTIF([1]クラス!$A$1:$A$1000, $B29),"",TRUE),"")
A30: 9 | B30: 武器の守り | E30: P | H30: 攻撃手段:武器 ガード+2 命中+5 | L30: =IF(OR(COUNTIF(クラス!$A$1:$A$1020, $B30),$B30="",COUNTIF(スキル一覧!$A$1:$A$3500, $B30)), "", "存在しない") -> 存在しない | M30: =IF(COUNTIF($B$1:$C29, $B30), "", "存在しない") -> 存在しない | N30: =IF(AND(A30<>"",L30="存在しない",M30="存在しない"),IF(COUNTIF([1]クラス!$A$1:$A$1000, $B30),"",TRUE),"") -> TRUE
A31: 10 | B31: 一閃撃 | C31: ブランデッシュ | E31: A | G31: 60 | H31: 攻撃手段:武器 物理+15 命中+25 判定:攻撃 | L31: =IF(OR(COUNTIF(クラス!$A$1:$A$1020, $B31),$B31="",COUNTIF(スキル一覧!$A$1:$A$3500, $B31)), "", "存在しない") -> 存在しない | M31: =IF(COUNTIF($B$1:$C30, $B31), "", "存在しない") | N31: =IF(AND(A31<>"",L31="存在しない",M31="存在しない"),IF(COUNTIF([1]クラス!$A$1:$A$1000, $B31),"",TRUE),"")
L32: =IF(OR(COUNTIF(クラス!$A$1:$A$1020, $B32),$B32="",COUNTIF(スキル一覧!$A$1:$A$3500, $B32)), "", "存在しない") | M32: =IF(COUNTIF($B$1:$C31, $B32), "", "存在しない") -> 存在しない | N32: =IF(AND(A32<>"",L32="存在しない",M32="存在しない"),IF(COUNTIF([1]クラス!$A$1:$A$1000, $B32),"",TRUE),"")
L33: =IF(OR(COUNTIF(クラス!$A$1:$A$1020, $B33),$B33="",COUNTIF(スキル一覧!$A$1:$A$3500, $B33)), "", "存在しない") | M33: =IF(COUNTIF($B$1:$C32, $B33), "", "存在しない") -> 存在しない | N33: =IF(AND(A33<>"",L33="存在しない",M33="存在しない"),IF(COUNTIF([1]クラス!$A$1:$A$1000, $B33),"",TRUE),"")
B34: フェンサー | L34: =IF(OR(COUNTIF(クラス!$A$1:$A$1020, $B34),$B34="",COUNTIF(スキル一覧!$A$1:$A$3500, $B34)), "", "存在しない") | M34: =IF(COUNTIF($B$1:$C33, $B34), "", "存在しない") -> 存在しない | N34: =IF(AND(A34<>"",L34="存在しない",M34="存在しない"),IF(COUNTIF([1]クラス!$A$1:$A$1000, $B34),"",TRUE),"")
A35: 1 | L35: =IF(OR(COUNTIF(クラス!$A$1:$A$1020, $B35),$B35="",COUNTIF(スキル一覧!$A$1:$A$3500, $B35)), "", "存在しない") | M35: =IF(COUNTIF($B$1:$C34, $B35), "", "存在しない") -> 存在しない | N35: =IF(AND(A35<>"",L35="存在しない",M35="存在しない"),IF(COUNTIF([1]クラス!$A$1:$A$1000, $B35),"",TRUE),"")
A36: 2 | B36: 闘気撃 | C36: オーラ・ストライク | E36: A | G36: 60 | H36: 攻撃手段:武器 物理+25 判定:攻撃 | L36: =IF(OR(COUNTIF(クラス!$A$1:$A$1020, $B36),$B36="",COUNTIF(スキル一覧!$A$1:$A$3500, $B36)), "", "存在しない") -> 存在しない | M36: =IF(COUNTIF($B$1:$C35, $B36), "", "存在しない") | N36: =IF(AND(A36<>"",L36="存在しない",M36="存在しない"),IF(COUNTIF([1]クラス!$A$1:$A$1000, $B36),"",TRUE),"")
A37: 3 | B37: 武器の扱い | E37: P | H37: 攻撃手段:武器 命中+10 | L37: =IF(OR(COUNTIF(クラス!$A$1:$A$1020, $B37),$B37="",COUNTIF(スキル一覧!$A$1:$A$3500, $B37)), "", "存在しない") -> 存在しない | M37: =IF(COUNTIF($B$1:$C36, $B37), "", "存在しない") | N37: =IF(AND(A37<>"",L37="存在しない",M37="存在しない"),IF(COUNTIF([1]クラス!$A$1:$A$1000, $B37),"",TRUE),"")
A38: 4 | L38: =IF(OR(COUNTIF(クラス!$A$1:$A$1020, $B38),$B38="",COUNTIF(スキル一覧!$A$1:$A$3500, $B38)), "", "存在しない") | M38: =IF(COUNTIF($B$1:$C37, $B38), "", "存在しない") -> 存在しない | N38: =IF(AND(A38<>"",L38="存在しない",M38="存在しない"),IF(COUNTIF([1]クラス!$A$1:$A$1000, $B38),"",TRUE),"")
A39: 5 | B39: 闘気速 | C39: オーラ・クイック | E39: A | G39: 40 | H39: 攻撃手段:武器 物理+15 速度+25 判定:速度 | L39: =IF(OR(COUNTIF(クラス!$A$1:$A$1020, $B39),$B39="",COUNTIF(スキル一覧!$A$1:$A$3500, $B39)), "", "存在しない") -> 存在しない | M39: =IF(COUNTIF($B$1:$C38, $B39), "", "存在しない") -> 存在しない | N39: =IF(AND(A39<>"",L39="存在しない",M39="存在しない"),IF(COUNTIF([1]クラス!$A$1:$A$1000, $B39),"",TRUE),"") -> TRUE
A40: 6 | E40: P | L40: =IF(OR(COUNTIF(クラス!$A$1:$A$1020, $B40),$B40="",COUNTIF(スキル一覧!$A$1:$A$3500, $B40)), "", "存在しない") | M40: =IF(COUNTIF($B$1:$C39, $B40), "", "存在しない") -> 存在しない | N40: =IF(AND(A40<>"",L40="存在しない",M40="存在しない"),IF(COUNTIF([1]クラス!$A$1:$A$1000, $B40),"",TRUE),"")
A41: 7 | L41: =IF(OR(COUNTIF(クラス!$A$1:$A$1020, $B41),$B41="",COUNTIF(スキル一覧!$A$1:$A$3500, $B41)), "", "存在しない") | M41: =IF(COUNTIF($B$1:$C40, $B41), "", "存在しない") -> 存在しない | N41: =IF(AND(A41<>"",L41="存在しない",M41="存在しない"),IF(COUNTIF([1]クラス!$A$1:$A$1000, $B41),"",TRUE),"")
A42: 8 | B42: 雄叫び | C42: ロアー | E42: A | G42: 40 | H42: 効果時間4t 攻撃+15 精神耐性+10 | L42: =IF(OR(COUNTIF(クラス!$A$1:$A$1020, $B42),$B42="",COUNTIF(スキル一覧!$A$1:$A$3500, $B42)), "", "存在しない") -> 存在しない | M42: =IF(COUNTIF($B$1:$C41, $B42), "", "存在しない") | N42: =IF(AND(A42<>"",L42="存在しない",M42="存在しない"),IF(COUNTIF([1]クラス!$A$1:$A$1000, $B42),"",TRUE),"")
...

Sheet スキル一覧
A1: 名前 | B1: ルビ | C1: 系統 | D1: 行動 | E1: HP消費 | F1: AP消費 | G1: 攻撃手段 | H1: 条件 | I1: 条件系統 | J1: ガード | K1: 回復 | L1: 物理 | M1: 魔法 | N1: 炎 | O1: 氷 | P1: 雷 | Q1: 毒 | R1: 光 | S1: 闇 | T1: 精神 | U1: 怯み | V1: 出血 | W1: 拘束 | X1: 幻覚 | Y1: Cr率 | Z1: Cr威力 | AA1: HP | AB1: 攻撃 | AC1: 防御 | AD1: 魔力 | AE1: 精神 | AF1: 速度 | AG1: 命中 | AH1: SIZ | AI1: 指揮 | AJ1: 戦術 | AK1: 威圧 | AL1: 看破 | AM1: 索敵 | AN1: 隠密 | AO1: 生存 | AP1: 罠設置 | AQ1: 農耕 | AR1: 伐採 | AS1: 採掘 | AT1: 錬成 | AU1: 統率 | AV1: 交渉 | AW1: 政治 | AX1: 信仰 | AY1: 物理耐性 | AZ1: 魔法耐性 | BA1: 炎耐性 | BB1: 氷耐性 | BC1: 雷耐性 | BD1: 毒耐性 | BE1: 光耐性 | BF1: 闇耐性 | BG1: 精神耐性 | BH1: 怯み耐性 | BI1: 出血耐性 | BJ1: 拘束耐性 | BK1: 幻覚耐性 | BL1: Cr率耐性 | BM1: Cr威力耐性 | BN1: 射程 | BO1: 範囲 | BP1: 対象 | BQ1: 効果 | BR1: 攻撃回数 | BS1: 攻撃追加 | BT1: 追加威力 | BU1: 判定 | BV1: 効果時間 | BW1: 待機 | BX1: 起動確認
A2: 1 | B2: 2 | C2: 3 | D2: 4 | E2: 8 | F2: 9 | G2: 5 | H2: 6 | I2: 7 | J2: 10 | L2: 11 | M2: 12 | N2: 13 | O2: 14 | P2: 15 | Q2: 16 | R2: 17 | S2: 18 | T2: 19 | U2: 20 | V2: 21 | W2: 22 | X2: 23 | Y2: 24 | Z2: 25 | AA2: 26 | AB2: 27 | AC2: 28 | AD2: 29 | AE2: 30 | AF2: 31 | AG2: 32 | AH2: 33 | AI2: 34 | AJ2: 35 | AK2: 36 | AL2: 37 | AM2: 38 | AN2: 39 | AO2: 40 | AP2: 41 | AQ2: 42 | AR2: 43 | AS2: 44 | AT2: 45 | AU2: 46 | AV2: 47 | AW2: 48 | AX2: 49 | AY2: 50 | AZ2: 51 | BA2: 52 | BB2: 53 | BC2: 54 | BD2: 55 | BE2: 56 | BF2: 57 | BG2: 58 | BH2: 59 | BI2: 60 | BJ2: 61 | BK2: 62 | BL2: 63 | BM2: 64 | BN2: 65 | BO2: 66 | BP2: 67 | BQ2: 68 | BR2: 69 | BS2: 70 | BT2: 71 | BU2: 72 | BV2: 73 | BW2: 74 | BX2: 75

Sheet Sheet5
